Workbook

Sheet Memo
A5: Scope
A6: The purpose of this workpaper is to verify the closing balances of trade payables as on 31/03/26.
A8: IPE: Listing
A9: Completeness: Completeness of IPE was ensured by tallying the balance of the schedule to the balance as per the financials.
A10: Accuracy: Accuracy of the IPE was ensured by Direct testing <<Refer Audit steps below>>
A12: Work Done
A13: 1. ET has obtained the schedule of Trade Payables as on March 31, 2026
A14: 2. ET has obtained the balance confirmations for the sample vendors. | F14: < Refer tab Balance Confirmations >
A15: 3. ET has obtained the subsequent status of the trade payables as on March 31, 2026 | F15: < Refer tab Invoice wise >
A16: 5. ET has obtained the Party wise list of the trade payables and reconcilied the balance with total trade payables. | F16: < Refer Tab Listing >
A17: 6. ET has verified the reinstatement of foreign debtors and verified the exchange rate taken for reinstatement from RBI website. | F17: < Refer tab forex rate >
A18: 7. ET has verified the disclosue of trade payables ageing as per the requirements of Schedule -3 (as amended). | F18: < Refer tab Schedule 3 >
A19: 8. ET has recalculate the Trade payables ageing . | F19: < Refer Tab Ageing >
A22: Observation
A23: Trade payables outstanding for more than 3 years for Related party and other than related party which needs a disclosure as per Ind AS 24 Related party dislosure and If there is any disputes with party that also has to be reported as per Schedule 3 .
A25: Conclusion
A26: Satisfactory

Sheet Reco & Summary 
A1: =Memo!A1 -> 0
A2: =Memo!A2 -> 0
A3: =Memo!A3 -> 0
A5: Purpose
A6: Purpose of this workpaper to summarize trade payable balance and bifurcate the TP balances into MSME and Non MSME.
A8: Reconciliation with Financial
A9: Particulars | B9: As per STIR Financials as on 31/03/26 | C9: As per working | D9: difference
A10: Due to micro and small enterprises (refer note 2.47) | B10: 123386123 | C10: =D25 -> 1.2333659e+08 | D10: =C10-B10 -> -49530.582
A11: Others creditors | B11: 482644475 | C11: =B25 -> 4.8241842e+08 | D11: =C11-B11 -> -226053.53
A13: - inter division | B13: 447634866 | C13: =F25 -> 4.4763486e+08 | D13: =C13-B13 -> -1.67
B14: =SUM(B10:B13) -> 1053665464 | C14: =SUM(C10:C13) -> 1.0533899e+09 | D14: =SUM(D10:D13) -> -275585.78 | E14: <<Immaterial>>
A16: Summary of TP listing
A17: Particulars | B17: Other than MSMED | D17: MSMED | F17: IDE | G17: Total | H17: Subsequently Status | I17: Subsequently Paid % | J17: ET Remarks
B18: Opex | C18: Capex | D18: Opex | E18: CAPEX
A19: Balance as per SL report (AP Liability) | B19: =SUMIFS('AP Liability Non MSME'!$R$21:$R$390,'AP Liability Non MSME'!$I$21:$I$390,B18) -> 1.8816731e+08 | C19: =SUMIFS('AP Liability Non MSME'!$R$21:$R$390,'AP Liability Non MSME'!$I$21:$I$390,C18) -> 306936.38 | D19: =SUMIFS('AP Liability MSME'!$R$21:$R$412,'AP Liability MSME'!$I$21:$I$412,'Reco & Summary '!D18) -> 47079777 | E19: =SUMIFS('AP Liability MSME'!$R$21:$R$412,'AP Liability MSME'!$I$21:$I$412,E18) -> 4872054.9 | F19: 0 | G19: =SUM(B19:F19) -> 2.4042608e+08 | H19: ='AP Liability Non MSME'!B15+'AP Liability MSME'!B15 -> 2.210367e+08 | I19: =H19/G19 -> 0.91935412
A20: SSS Accrual | B20: =SUMIFS('SSS Accrual Non MSME'!$N$21:$N$226,'SSS Accrual Non MSME'!$O$21:$O$226,'Reco & Summary '!B18) -> 1.535431e+08 | C20: =SUMIFS('SSS Accrual Non MSME'!$N$21:$N$226,'SSS Accrual Non MSME'!$O$21:$O$226,C18) -> 689531.8 | D20: =SUMIFS('SSS Accrual MSME'!$N$21:$N$195,'SSS Accrual MSME'!$O$21:$O$195,'Reco & Summary '!D18) -> 19759203 | E20: =SUMIFS('SSS Accrual MSME'!$N$21:$N$195,'SSS Accrual MSME'!$O$21:$O$195,E18) -> 6489622.9 | F20: 0 | G20: =SUM(B20:F20) -> 1.8048146e+08 | H20: ='SSS Accrual Non MSME'!B15+'SSS Accrual MSME'!B15 -> 1.7985262e+08 | I20: =H20/G20 -> 0.99651579
A21: Open PO Accruals | B21: =SUMIFS('PO Accrual Non MSME'!$O$19:$O$229,'PO Accrual Non MSME'!$E$19:$E$229,'Reco & Summary '!B18) -> 1.3424228e+08 | C21: =SUMIFS('PO Accrual Non MSME'!$O$19:$O$229,'PO Accrual Non MSME'!$E$19:$E$229,'Reco & Summary '!C18) -> 1084366 | D21: =SUMIFS('PO Accrual MSME'!$O$20:$O$212,'PO Accrual MSME'!$E$20:$E$212,'Reco & Summary '!D18) -> 56497612 | E21: =SUMIFS('PO Accrual MSME'!$O$20:$O$212,'PO Accrual MSME'!$E$20:$E$212,E18) -> 16601942 | F21: 0 | G21: =SUM(B21:F21) -> 2.084262e+08
A22: ESB Accruals | F22: ='ESB accrual '!I9 -> 28616339 | G22: =SUM(B22:F22) -> 28616339
A23: GEIIPL ESOP/RSU liability F.Y. 2025-26 | F23: =-'ESOP & RSU'!G17-'ESOP & RSU'!H27 -> 309752848 | G23: =SUM(B23:F23) -> 309752848
A24: IBS DT accruals | B24: 6465731.7 | F24: 1.0926568e+08 | G24: =SUM(B24:F24) -> 1.1573141e+08
B25: =SUM(B19:B24) -> 4.8241842e+08 | C25: =SUM(C19:C24) -> 2080834.2 | D25: =SUM(D19:D24) -> 1.2333659e+08 | E25: =SUM(E19:E24) -> 27963620 | F25: =SUM(F19:F24) -> 4.4763486e+08 | G25: =SUM(G19:G24) -> 1.0834343e+09

Sheet Schedule III 
A1: =Memo!A1 -> 0
A2: =Memo!A2 -> 0
A3: =Memo!A3 -> 0
A5: Purpose
A6: To verify the correctness of diclosure of Trade payables ageing as per Schedule III
A8: Work done | H8: *Excl Interdivison and Capital Creditros
A9: ET has obtained the Trade payable listing from the client.
A10: ET has reperformed the ageing calculation.
A11: Amount in MSME includes Capex amount pertaining to MSME
G12: Amount in Rs.
A13: Particulars | B13: Not Due | C13: Less than 1 Year | D13: 1-2 years | E13: 2-3 years | F13: More than 3 years | G13: Total
A14: (i) MSME | B14: =SUMIFS('AP Liability MSME'!R:R,'AP Liability MSME'!AQ:AQ,'Schedule III '!B13,'AP Liability MSME'!I:I,"Opex")+SUMIFS('SSS Accrual MSME'!$N:$N,'SSS Accrual MSME'!$AO:$AO,'Schedule III '!B13,'SSS Accrual MSME'!$O:$O,"Opex")+SUMIFS('PO Accrual MSME'!$O:$O,'PO Accrual MSME'!$E:$E,"Opex") -> 1.2330423e+08 | C14: =SUMIFS('AP Liability MSME'!R:R,'AP Liability MSME'!AQ:AQ,C13,'AP Liability MSME'!I:I,"Opex")+SUMIFS('SSS Accrual MSME'!$N:$N,'SSS Accrual MSME'!$AO:$AO,'Schedule III '!C13,'SSS Accrual MSME'!$O:$O,"Opex") -> 32363.5 | D14: 0 | E14: 0 | F14: 0 | G14: =SUM(B14:F14) -> 1.2333659e+08
A15: (ii) Others | B15: =SUMIFS('AP Liability Non MSME'!$R:$R,'AP Liability Non MSME'!$AP:$AP,'Schedule III '!B13,'AP Liability Non MSME'!I:I,"Opex")+SUMIFS('SSS Accrual Non MSME'!$N:$N,'SSS Accrual Non MSME'!$AO:$AO,'Schedule III '!B13,'SSS Accrual Non MSME'!O:O,"Opex")+SUMIFS('PO Accrual Non MSME'!O:O,'PO Accrual Non MSME'!E:E,"Opex")+'Reco & Summary '!B24 -> 4.5870159e+08 | C15: =SUMIFS('AP Liability Non MSME'!$R:$R,'AP Liability Non MSME'!$AP:$AP,'Schedule III '!C13,'AP Liability Non MSME'!I:I,"Opex")+SUMIFS('SSS Accrual Non MSME'!$N:$N,'SSS Accrual Non MSME'!$AO:$AO,'Schedule III '!C13,'SSS Accrual Non MSME'!O:O,"Opex") -> 23209050 | D15: =SUMIFS('AP Liability Non MSME'!$R:$R,'AP Liability Non MSME'!$AP:$AP,'Schedule III '!D13,'AP Liability Non MSME'!I:I,"Opex")+SUMIFS('SSS Accrual Non MSME'!$N:$N,'SSS Accrual Non MSME'!$AO:$AO,'Schedule III '!D13,'SSS Accrual Non MSME'!O:O,"Opex") -> 166497.26 | E15: =SUMIFS('AP Liability Non MSME'!$R:$R,'AP Liability Non MSME'!$AP:$AP,'Schedule III '!E13,'AP Liability Non MSME'!I:I,"Opex")+SUMIFS('SSS Accrual Non MSME'!$N:$N,'SSS Accrual Non MSME'!$AO:$AO,'Schedule III '!E13,'SSS Accrual Non MSME'!O:O,"Opex") -> 19103.131 | F15: =SUMIFS('AP Liability Non MSME'!$R:$R,'AP Liability Non MSME'!$AP:$AP,'Schedule III '!F13,'AP Liability Non MSME'!I:I,"Opex")+SUMIFS('SSS Accrual Non MSME'!$N:$N,'SSS Accrual Non MSME'!$AO:$AO,'Schedule III '!F13,'SSS Accrual Non MSME'!O:O,"Opex") -> 322182.08 | G15: =SUM(B15:F15) -> 4.8241842e+08
A16: (iii) Disputed dues - MSME | G16: =SUM(C16:F16) -> 0
A17: (iv) Disputed dues - Others | G17: =SUM(C17:F17) -> 0
B18: Balance as per schedule | G18: =SUM(G14:G15) -> 6.0575501e+08
B19: As per Financials | G19: 606030598
B20: Diff | G20: =G18-G19 -> -275584.11
F25: ap non
E26: Row Labels | F26: Sum of Amount as per RBI
E27: ABB INDIA LIMITED A37150 | F27: 10404.17
E28: Ambika Water Supply A38198 | F28: 132115.25
E29: Amplus Kn Solar Private Limited A37782 | F29: 9530759.7
E30: APSIS AEROCOM LIMITED | F30: 266717.51
E31: BAKER HUGHES DIGITAL SOLUTIONS GMBH N63671 | F31: 55253.164
E32: Bengaluru Marriott Hotel Whitefield A37515 | F32: 136880
E33: Bharti Airtel Limited A38979 | F33: 1548966.2
E34: BLUE DART EXPRESS LIMITED A35832 | F34: 11202.58
E35: CAPGEMINI TECHNOLOGY SERVICES INDIA LIMITED A16348 | F35: 3223584
E36: CHUBB SYSTEMS PRIVATE LIMITED A38431 | F36: 40411.8
E37: CISCO SYSTEMS CAPITAL INDIA PRIVATE LIMITED A37210 | F37: 10711526
E38: CONVERGINT INDIA PRIVATE LIMITED A36904 | F38: 444681.36
... E106: Grand Total | F106: 1.8847425e+08

Sheet AP Liability Non MSME
A1: =Memo!A1 -> 0 | U1: ='AP Liability MSME'!U1 -> 46112
A2: =Memo!A2 -> 0
A3: =Memo!A3 -> 0
A5: Work Done
A6: 1. ET has obtained the schedule for AP Liability (Non-MSME).
A7: 2. ET has verified the exchange rate considered for closing payable amount.
A8: 3. ET has recomputed the ageing of invoices payable from due date.
A9: 4. ET has checked the computation of due date and performed 3 way match on sample basis.
A11: Summary
A13: Particulars | B13: Amount
A14: Payable Amount | B14: =R19 -> 1.8847425e+08
A15: Subsequently Paid | B15: =AN19 -> 1.6907817e+08
A16: Subsequently Paid % | B16: =B15/B14 -> 0.89708896
A18: AP Liability Schedule - Non MSME
R19: =SUM(R21:R390) -> 1.8847425e+08 | S19: =SUM(S21:S390) -> 535453.67 | V19: =SUM(V21:V390) -> 4838174.6 | W19: =SUM(W21:W390) -> 570165.9 | X19: =SUM(X21:X390) -> 253681.24 | Y19: =SUM(Y21:Y390) -> 0 | Z19: =SUM(Z21:Z390) -> 125280 | AA19: =SUM(AA21:AA390) -> 185600.39 | AB19: =SUM(AB21:AB390) -> 322182.08 | AC19: =SUM(AC21:AC390) -> 1.8217916e+08 | AL19: =SUM(AL20:AL1900) -> 1.8847425e+08 | AM19: =SUM(AM20:AM1900) -> 0 | AN19: =SUM(AN20:AN1900) -> 1.6907817e+08 | AO19: 46112
A20: Division | B20: Company Code | C20: Account Code | D20: Account Description | E20: Vendor Name | F20: Related Party | G20: Foreign / Domestic | H20: Unique | I20: Nature (Capital/Trade) | J20: Invoice Number | K20: PO Number | L20: Invoice Date | M20: Currency | N20: Invoice Original Amount | O20: MOR Rate | P20: Invoice Amount INR | Q20: RBI Rate | R20: Amount as per RBI | S20: FX_Diff | T20: MSMED | U20: Ageing | V20: 0-30 days | W20: 30-60 days | X20: 60-90 days | Y20: 90-120 days | Z20: 120-180 days | AA20: 180 Days-3 year | AB20: >3 Years | AC20: Not Due | AD20: Invoice Id | AE20: Reson for more than 180 days/debit balances/No GE entity payables | AF20: Subsequent payment Doc # | AG20: Date of subsequent payment | AH20: Due date | AJ20: Currency | AK20: Exchange Rate | AL20: Amount in INR | AM20: Difference | AN20: Subsequently Paid | AO20: No. of Days | AP20: Ageing Bracket | AU20: =AS20+AS19+AS22+'AP Liability MSME'!AT19 -> 0
A21: GE India Industrial Pvt Ltd - GEITC | B21: GR16 | C21: 2070201000 | D21: Trade Accounts Payable-Subledge | E21: Gartner India Research and Advisory Services Pvt. Ltd. A37407 | F21: Non-IBS | G21: Domestic | I21: Opex | J21: IN5020806 | K21: 100069560 | L21: 45959 | M21: INR | N21: 107136 | O21: 1 | P21: =N21*O21 -> 107136 | Q21: 1 | R21: =N21*Q21 -> 107136 | S21: =R21-P21 -> 0 | T21: Non-MSME | U21: =$U$1-AH21 -> 33 | V21: 0 | W21: =R21 -> 107136 | X21: 0 | Y21: 0 | Z21: 0 | AA21: 0 | AB21: 0 | AC21: 0 | AD21: 38556214 | AE21: As per User confirmation Invoice cancelled in Apr26 | AH21: 46079 | AJ21: =M21 -> INR | AK21: 1 | AL21: =N21*AK21 -> 107136 | AM21: =R21-AL21 -> 0 | AO21: =$AO$19-AH21 -> 33 | AP21: =IF(AO21<0,"Not Due",IF(AO21<366,"Less than 1 year",IF(AO21<731,"1-2 years",IF(AO21<1096,"2-3 years","More than 3 years")))) -> Less than 1 year | AU21: =AS19+'AP Liability MSME'!AT19 -> 0
A22: GE India Industrial Pvt Ltd - GEITC | B22: GR16 | C22: 2070201000 | D22: Trade Accounts Payable-Subledge | E22: INDO-MIM LIMITED | F22: Non-IBS | G22: Domestic | I22: Opex | J22: D-D2815/2526 | K22: 100071136 | L22: 46094 | M22: INR | N22: 5140.44 | O22: 1 | P22: =N22*O22 -> 5140.44 | Q22: 1 | R22: =N22*Q22 -> 5140.44 | S22: =R22-P22 -> 0 | T22: Non-MSME | U22: =$U$1-AH22 -> -12 | V22: 0 | W22: 0 | X22: 0 | Y22: 0 | Z22: 0 | AA22: 0 | AB22: 0 | AC22: =R22 -> 5140.44 | AD22: 39011958 | AE22: Not Due | AF22: 88161 | AG22: 46121 | AH22: 46124 | AJ22: =M22 -> INR | AK22: 1 | AL22: =N22*AK22 -> 5140.44 | AM22: =R22-AL22 -> 0 | AN22: =AL22 -> 5140.44 | AO22: =$AO$19-AH22 -> -12 | AP22: =IF(AO22<0,"Not Due",IF(AO22<366,"Less than 1 year",IF(AO22<731,"1-2 years",IF(AO22<1096,"2-3 years","More than 3 years")))) -> Not Due | AU22: =AS21+'AP Liability MSME'!AT20+'SSS Accrual Non MSME'!AR19 -> 0
A23: GE India Industrial Pvt Ltd - GEITC | B23: GR16 | C23: 2070201000 | D23: Trade Accounts Payable-Subledge | E23: GENPACT INDIA PRIVATE LIMITED A37168 | F23: Non-IBS | G23: Domestic | I23: Opex | J23: B2ZXKA17929 | K23: 100066859 | L23: 46023 | M23: INR | N23: 197264.16 | O23: 1 | P23: =N23*O23 -> 197264.16 | Q23: 1 | R23: =N23*Q23 -> 197264.16 | S23: =R23-P23 -> 0 | T23: Non-MSME | U23: =$U$1-AH23 -> -61 | V23: 0 | W23: 0 | X23: 0 | Y23: 0 | Z23: 0 | AA23: 0 | AB23: 0 | AC23: =R23 -> 197264.16 | AD23: 38718522 | AE23: Not Due | AF23: 88955 | AG23: 46168 | AH23: 46173 | AJ23: =M23 -> INR | AK23: 1 | AL23: =N23*AK23 -> 197264.16 | AM23: =R23-AL23 -> 0 | AN23: =AL23 -> 197264.16 | AO23: =$AO$19-AH23 -> -61 | AP23: =IF(AO23<0,"Not Due",IF(AO23<366,"Less than 1 year",IF(AO23<731,"1-2 years",IF(AO23<1096,"2-3 years","More than 3 years")))) -> Not Due
A24: GE India Industrial Pvt Ltd - GEITC | B24: GR16 | C24: 2070201000 | D24: Trade Accounts Payable-Subledge | E24: Element14 India Private Limited A36095 | F24: Non-IBS | G24: Domestic | I24: Opex | J24: 1046566 | K24: 100070712 | L24: 46070 | M24: INR | N24: 8763.04 | O24: 1 | P24: =N24*O24 -> 8763.04 | Q24: 1 | R24: =N24*Q24 -> 8763.04 | S24: =R24-P24 -> 0 | T24: Non-MSME | U24: =$U$1-AH24 -> -78 | V24: 0 | W24: 0 | X24: 0 | Y24: 0 | Z24: 0 | AA24: 0 | AB24: 0 | AC24: =R24 -> 8763.04 | AD24: 38922414 | AE24: Not Due | AF24: 89210 | AG24: 46188 | AH24: 46190 | AJ24: =M24 -> INR | AK24: 1 | AL24: =N24*AK24 -> 8763.04 | AM24: =R24-AL24 -> 0 | AN24: =AL24 -> 8763.04 | AO24: =$AO$19-AH24 -> -78 | AP24: =IF(AO24<0,"Not Due",IF(AO24<366,"Less than 1 year",IF(AO24<731,"1-2 years",IF(AO24<1096,"2-3 years","More than 3 years")))) -> Not Due
A25: GE India Industrial Pvt Ltd - GEITC | B25: GR16 | C25: 2070201000 | D25: Trade Accounts Payable-Subledge | E25: Tata Consultancy Services Limited A11987 | F25: Non-IBS | G25: Domestic | I25: Opex | J25: KADI526013446 | K25: 100067695 | L25: 46078 | M25: INR | N25: 216000 | O25: 1 | P25: =N25*O25 -> 216000 | Q25: 1 | R25: =N25*Q25 -> 216000 | S25: =R25-P25 -> 0 | T25: Non-MSME | U25: =$U$1-AH25 -> -116 | V25: 0 | W25: 0 | X25: 0 | Y25: 0 | Z25: 0 | AA25: 0 | AB25: 0 | AC25: =R25 -> 216000 | AD25: 38976983 | AE25: Not Due | AH25: 46228 | AJ25: =M25 -> INR | AK25: 1 | AL25: =N25*AK25 -> 216000 | AM25: =R25-AL25 -> 0 | AO25: =$AO$19-AH25 -> -116 | AP25: =IF(AO25<0,"Not Due",IF(AO25<366,"Less than 1 year",IF(AO25<731,"1-2 years",IF(AO25<1096,"2-3 years","More than 3 years")))) -> Not Due
A26: GE India Industrial Pvt Ltd - GEITC | B26: GR16 | C26: 2070201000 | D26: Trade Accounts Payable-Subledge | E26: PERSOL INDIA PRIVATE LIMITED | F26: Non-IBS | G26: Domestic | I26: Opex | J26: KAT2526EH00155 | K26: 100068129 | L26: 46080 | M26: INR | N26: 174656.78 | O26: 1 | P26: =N26*O26 -> 174656.78 | Q26: 1 | R26: =N26*Q26 -> 174656.78 | S26: =R26-P26 -> 0 | T26: Non-MSME | U26: =$U$1-AH26 -> -28 | V26: 0 | W26: 0 | X26: 0 | Y26: 0 | Z26: 0 | AA26: 0 | AB26: 0 | AC26: =R26 -> 174656.78 | AD26: 38994055 | AE26: Not Due | AF26: 88417 | AG26: 46136 | AH26: 46140 | AJ26: =M26 -> INR | AK26: 1 | AL26: =N26*AK26 -> 174656.78 | AM26: =R26-AL26 -> 0 | AN26: =AL26 -> 174656.78 | AO26: =$AO$19-AH26 -> -28 | AP26: =IF(AO26<0,"Not Due",IF(AO26<366,"Less than 1 year",IF(AO26<731,"1-2 years",IF(AO26<1096,"2-3 years","More than 3 years")))) -> Not Due
A27: GE India Industrial Pvt Ltd - GEITC | B27: GR16 | C27: 2070201000 | D27: Trade Accounts Payable-Subledge | E27: Superseva Global Services Private Limited A38849 | F27: Non-IBS | G27: Domestic | I27: Opex | J27: FEB/25-26/5431 | K27: 100067740 | L27: 46083 | M27: INR | N27: 43074.28 | O27: 1 | P27: =N27*O27 -> 43074.28 | Q27: 1 | R27: =N27*Q27 -> 43074.28 | S27: =R27-P27 -> 0 | T27: Non-MSME | U27: =$U$1-AH27 -> -16 | V27: 0 | W27: 0 | X27: 0 | Y27: 0 | Z27: 0 | AA27: 0 | AB27: 0 | AC27: =R27 -> 43074.28 | AD27: 38976190 | AE27: Not Due | AF27: Payment on hold as per Notice received from GST department | AH27: 46128 | AJ27: =M27 -> INR | AK27: 1 | AL27: =N27*AK27 -> 43074.28 | AM27: =R27-AL27 -> 0 | AO27: =$AO$19-AH27 -> -16 | AP27: =IF(AO27<0,"Not Due",IF(AO27<366,"Less than 1 year",IF(AO27<731,"1-2 years",IF(AO27<1096,"2-3 years","More than 3 years")))) -> Not Due
A28: GE India Industrial Pvt Ltd - GEITC | B28: GR16 | C28: 2070201000 | D28: Trade Accounts Payable-Subledge | E28: Tata Consultancy Services Limited A11987 | F28: Non-IBS | G28: Domestic | I28: Opex | J28: KADI526012304 | K28: 100066399 | L28: 46049 | M28: INR | N28: 2511244.1 | O28: 1 | P28: =N28*O28 -> 2511244.1 | Q28: 1 | R28: =N28*Q28 -> 2511244.1 | S28: =R28-P28 -> 0 | T28: Non-MSME | U28: =$U$1-AH28 -> -87 | V28: 0 | W28: 0 | X28: 0 | Y28: 0 | Z28: 0 | AA28: 0 | AB28: 0 | AC28: =R28 -> 2511244.1 | AD28: 38838440 | AE28: Not Due | AH28: 46199 | AJ28: =M28 -> INR | AK28: 1 | AL28: =N28*AK28 -> 2511244.1 | AM28: =R28-AL28 -> 0 | AO28: =$AO$19-AH28 -> -87 | AP28: =IF(AO28<0,"Not Due",IF(AO28<366,"Less than 1 year",IF(AO28<731,"1-2 years",IF(AO28<1096,"2-3 years","More than 3 years")))) -> Not Due
A29: GE India Industrial Pvt Ltd - GEITC | B29: GR16 | C29: 2070201000 | D29: Trade Accounts Payable-Subledge | E29: SEDIN TECHNOLOGIES PVT LTD A36624 | F29: Non-IBS | G29: Domestic | I29: Opex | J29: 50001954 | K29: 100070049 | L29: 46091 | M29: INR | N29: 647862.3 | O29: 1 | P29: =N29*O29 -> 647862.3 | Q29: 1 | R29: =N29*Q29 -> 647862.3 | S29: =R29-P29 -> 0 | T29: Non-MSME | U29: =$U$1-AH29 -> -24 | V29: 0 | W29: 0 | X29: 0 | Y29: 0 | Z29: 0 | AA29: 0 | AB29: 0 | AC29: =R29 -> 647862.3 | AD29: 39006193 | AE29: Not Due | AF29: 88379 | AG29: 46133 | AH29: 46136 | AJ29: =M29 -> INR | AK29: 1 | AL29: =N29*AK29 -> 647862.3 | AM29: =R29-AL29 -> 0 | AN29: =AL29 -> 647862.3 | AO29: =$AO$19-AH29 -> -24 | AP29: =IF(AO29<0,"Not Due",IF(AO29<366,"Less than 1 year",IF(AO29<731,"1-2 years",IF(AO29<1096,"2-3 years","More than 3 years")))) -> Not Due
A30: GE India Industrial Pvt Ltd - GEITC | B30: GR16 | C30: 2070201000 | D30: Trade Accounts Payable-Subledge | E30: MOUSER ELECTRONICS INC. A02649 | F30: Non-IBS | G30: Foreign | I30: Opex | J30: 89076855 | K30: 100071065 | L30: 46084 | M30: USD | N30: 1320.28 | O30: 91.03395 | P30: =N30*O30 -> 120190.3 | Q30: 94.6543 | R30: =N30*Q30 -> 124970.18 | S30: =R30-P30 -> 4779.8757 | T30: Non-MSME | U30: =$U$1-AH30 -> -62 | V30: 0 | W30: 0 | X30: 0 | Y30: 0 | Z30: 0 | AA30: 0 | AB30: 0 | AC30: =R30 -> 124970.18 | AD30: 38987412 | AE30: Not Due | AF30: 90008291 | AG30: 46174 | AH30: 46174 | AJ30: =M30 -> USD | AK30: 94.6543 | AL30: =N30*AK30 -> 124970.18 | AM30: =R30-AL30 -> 0 | AN30: =AL30 -> 124970.18 | AO30: =$AO$19-AH30 -> -62 | AP30: =IF(AO30<0,"Not Due",IF(AO30<366,"Less than 1 year",IF(AO30<731,"1-2 years",IF(AO30<1096,"2-3 years","More than 3 years")))) -> Not Due
A31: GE India Industrial Pvt Ltd - GEITC | B31: GR16 | C31: 2070201000 | D31: Trade Accounts Payable-Subledge | E31: GENPACT INDIA PRIVATE LIMITED A37168 | F31: Non-IBS | G31: Domestic | I31: Opex | J31: B1Z3TS16731 | K31: 100064664 | L31: 46013 | M31: INR | N31: 1350745.2 | O31: 1 | P31: =N31*O31 -> 1350745.2 | Q31: 1 | R31: =N31*Q31 -> 1350745.2 | S31: =R31-P31 -> 0 | T31: Non-MSME | U31: =$U$1-AH31 -> -51 | V31: 0 | W31: 0 | X31: 0 | Y31: 0 | Z31: 0 | AA31: 0 | AB31: 0 | AC31: =R31 -> 1350745.2 | AD31: 38697159 | AE31: Not Due | AF31: 88807 | AG31: 46160 | AH31: 46163 | AJ31: =M31 -> INR | AK31: 1 | AL31: =N31*AK31 -> 1350745.2 | AM31: =R31-AL31 -> 0 | AN31: =AL31 -> 1350745.2 | AO31: =$AO$19-AH31 -> -51 | AP31: =IF(AO31<0,"Not Due",IF(AO31<366,"Less than 1 year",IF(AO31<731,"1-2 years",IF(AO31<1096,"2-3 years","More than 3 years")))) -> Not Due
A32: GE India Industrial Pvt Ltd - GEITC | B32: GR16 | C32: 2070201000 | D32: Trade Accounts Payable-Subledge | E32: GENPACT INDIA PRIVATE LIMITED A37168 | F32: Non-IBS | G32: Domestic | I32: Opex | J32: B2ZXKA17447 | K32: 100068107 | L32: 45971 | M32: INR | N32: 222879.6 | O32: 1 | P32: =N32*O32 -> 222879.6 | Q32: 1 | R32: =N32*Q32 -> 222879.6 | S32: =R32-P32 -> 0 | T32: Non-MSME | U32: =$U$1-AH32 -> -9 | V32: 0 | W32: 0 | X32: 0 | Y32: 0 | Z32: 0 | AA32: 0 | AB32: 0 | AC32: =R32 -> 222879.6 | AD32: 38514019 | AE32: Not Due | AF32: 88097 | AG32: 46118 | AH32: 46121 | AJ32: =M32 -> INR | AK32: 1 | AL32: =N32*AK32 -> 222879.6 | AM32: =R32-AL32 -> 0 | AN32: =AL32 -> 222879.6 | AO32: =$AO$19-AH32 -> -9 | AP32: =IF(AO32<0,"Not Due",IF(AO32<366,"Less than 1 year",IF(AO32<731,"1-2 years",IF(AO32<1096,"2-3 years","More than 3 years")))) -> Not Due
A33: GE India Industrial Pvt Ltd - GEITC | B33: GR16 | C33: 2070201000 | D33: Trade Accounts Payable-Subledge | E33: GENPACT INDIA PRIVATE LIMITED A37168 | F33: Non-IBS | G33: Domestic | I33: Opex | J33: B2ZXKA17671 | K33: 100068631 | L33: 45996 | M33: INR | N33: 354024 | O33: 1 | P33: =N33*O33 -> 354024 | Q33: 1 | R33: =N33*Q33 -> 354024 | S33: =R33-P33 -> 0 | T33: Non-MSME | U33: =$U$1-AH33 -> -34 | V33: 0 | W33: 0 | X33: 0 | Y33: 0 | Z33: 0 | AA33: 0 | AB33: 0 | AC33: =R33 -> 354024 | AD33: 38613688 | AE33: Not Due | AF33: 88495 | AG33: 46143 | AH33: 46146 | AJ33: =M33 -> INR | AK33: 1 | AL33: =N33*AK33 -> 354024 | AM33: =R33-AL33 -> 0 | AN33: =AL33 -> 354024 | AO33: =$AO$19-AH33 -> -34 | AP33: =IF(AO33<0,"Not Due",IF(AO33<366,"Less than 1 year",IF(AO33<731,"1-2 years",IF(AO33<1096,"2-3 years","More than 3 years")))) -> Not Due
A34: GE India Industrial Pvt Ltd - GEITC | B34: GR16 | C34: 2070201000 | D34: Trade Accounts Payable-Subledge | E34: QUEST GLOBAL ENGINEERING SERVICES PRIVATE LIMITED A36314 | F34: Non-IBS | G34: Domestic | I34: Opex | J34: 20250765616 | K34: 100065605 | L34: 46034 | M34: INR | N34: 362232 | O34: 1 | P34: =N34*O34 -> 362232 | Q34: 1 | R34: =N34*Q34 -> 362232 | S34: =R34-P34 -> 0 | T34: Non-MSME | U34: =$U$1-AH34 -> -12 | V34: 0 | W34: 0 | X34: 0 | Y34: 0 | Z34: 0 | AA34: 0 | AB34: 0 | AC34: =R34 -> 362232 | AD34: 38765216 | AE34: Not Due | AF34: 88152 | AG34: 46121 | AH34: 46124 | AJ34: =M34 -> INR | AK34: 1 | AL34: =N34*AK34 -> 362232 | AM34: =R34-AL34 -> 0 | AN34: =AL34 -> 362232 | AO34: =$AO$19-AH34 -> -12 | AP34: =IF(AO34<0,"Not Due",IF(AO34<366,"Less than 1 year",IF(AO34<731,"1-2 years",IF(AO34<1096,"2-3 years","More than 3 years")))) -> Not Due
A35: GE India Industrial Pvt Ltd - GEITC | B35: GR16 | C35: 2070201000 | D35: Trade Accounts Payable-Subledge | E35: CHUBB SYSTEMS PRIVATE LIMITED A38431 | F35: Non-IBS | G35: Domestic | I35: Opex | J35: 5114105277 | K35: 100070721 | L35: 46079 | M35: INR | N35: 36290.3 | O35: 1 | P35: =N35*O35 -> 36290.3 | Q35: 1 | R35: =N35*Q35 -> 36290.3 | S35: =R35-P35 -> 0 | T35: Non-MSME | U35: =$U$1-AH35 -> -12 | V35: 0 | W35: 0 | X35: 0 | Y35: 0 | Z35: 0 | AA35: 0 | AB35: 0 | AC35: =R35 -> 36290.3 | AD35: 38981680 | AE35: Not Due | AF35: 88160 | AG35: 46121 | AH35: 46124 | AJ35: =M35 -> INR | AK35: 1 | AL35: =N35*AK35 -> 36290.3 | AM35: =R35-AL35 -> 0 | AN35: =AL35 -> 36290.3 | AO35: =$AO$19-AH35 -> -12 | AP35: =IF(AO35<0,"Not Due",IF(AO35<366,"Less than 1 year",IF(AO35<731,"1-2 years",IF(AO35<1096,"2-3 years","More than 3 years")))) -> Not Due
A36: GE India Industrial Pvt Ltd - GEITC | B36: GR16 | C36: 2070201000 | D36: Trade Accounts Payable-Subledge | E36: Wonder Wash Pvt Ltd A37913 | F36: Non-IBS | G36: Domestic | I36: Opex | J36: WW325/2025-26 | K36: 100070183 | L36: 46085 | M36: INR | N36: 16182 | O36: 1 | P36: =N36*O36 -> 16182 | Q36: 1 | R36: =N36*Q36 -> 16182 | S36: =R36-P36 -> 0 | T36: Non-MSME | U36: =$U$1-AH36 -> -3 | V36: 0 | W36: 0 | X36: 0 | Y36: 0 | Z36: 0 | AA36: 0 | AB36: 0 | AC36: =R36 -> 16182 | AD36: 38977112 | AE36: Not Due | AF36: 88023 | AG36: 46113 | AH36: 46115 | AJ36: =M36 -> INR | AK36: 1 | AL36: =N36*AK36 -> 16182 | AM36: =R36-AL36 -> 0 | AN36: =AL36 -> 16182 | AO36: =$AO$19-AH36 -> -3 | AP36: =IF(AO36<0,"Not Due",IF(AO36<366,"Less than 1 year",IF(AO36<731,"1-2 years",IF(AO36<1096,"2-3 years","More than 3 years")))) -> Not Due
A37: GE India Industrial Pvt Ltd - GEITC | B37: GR16 | C37: 2070201000 | D37: Trade Accounts Payable-Subledge | E37: Infiniti Power Private Limited A37094 | F37: Non-IBS | G37: Domestic | I37: Opex | J37: 252900487 | K37: 100070245 | L37: 46086 | M37: INR | N37: 88639.08 | O37: 1 | P37: =N37*O37 -> 88639.08 | Q37: 1 | R37: =N37*Q37 -> 88639.08 | S37: =R37-P37 -> 0 | T37: Non-MSME | U37: =$U$1-AH37 -> -19 | V37: 0 | W37: 0 | X37: 0 | Y37: 0 | Z37: 0 | AA37: 0 | AB37: 0 | AC37: =R37 -> 88639.08 | AD37: 38982924 | AE37: Not Due | AF37: 88299 | AG37: 46128 | AH37: 46131 | AJ37: =M37 -> INR | AK37: 1 | AL37: =N37*AK37 -> 88639.08 | AM37: =R37-AL37 -> 0 | AN37: =AL37 -> 88639.08 | AO37: =$AO$19-AH37 -> -19 | AP37: =IF(AO37<0,"Not Due",IF(AO37<366,"Less than 1 year",IF(AO37<731,"1-2 years",IF(AO37<1096,"2-3 years","More than 3 years")))) -> Not Due
A38: GE India Industrial Pvt Ltd - GEITC | B38: GR16 | C38: 2070201000 | D38: Trade Accounts Payable-Subledge | E38: MOUSER ELECTRONICS INC. A02649 | F38: Non-IBS | G38: Foreign | I38: Opex | J38: 88817649 | K38: 100070864 | L38: 46069 | M38: USD | N38: 42.02 | O38: 91.82425 | P38: =N38*O38 -> 3858.455 | Q38: 94.6543 | R38: =N38*Q38 -> 3977.3737 | S38: =R38-P38 -> 118.9187 | T38: Non-MSME | U38: =$U$1-AH38 -> -47 | V38: 0 | W38: 0 | X38: 0 | Y38: 0 | Z38: 0 | AA38: 0 | AB38: 0 | AC38: =R38 -> 3977.3737 | AD38: 38939214 | AE38: Not Due | AF38: 90008285 | AG38: 46156 | AH38: 46159 | AJ38: =M38 -> USD | AK38: 94.6543 | AL38: =N38*AK38 -> 3977.3737 | AM38: =R38-AL38 -> 0 | AN38: =AL38 -> 3977.3737 | AO38: =$AO$19-AH38 -> -47 | AP38: =IF(AO38<0,"Not Due",IF(AO38<366,"Less than 1 year",IF(AO38<731,"1-2 years",IF(AO38<1096,"2-3 years","More than 3 years")))) -> Not Due
A39: GE India Industrial Pvt Ltd - GEITC | B39: GR16 | C39: 2070201000 | D39: Trade Accounts Payable-Subledge | E39: GENPACT INDIA PRIVATE LIMITED A37168 | F39: Non-IBS | G39: Domestic | I39: Opex | J39: B2ZXKA17986 | K39: 100065489 | L39: 46030 | M39: INR | N39: 446796 | O39: 1 | P39: =N39*O39 -> 446796 | Q39: 1 | R39: =N39*Q39 -> 446796 | S39: =R39-P39 -> 0 | T39: Non-MSME | U39: =$U$1-AH39 -> -68 | V39: 0 | W39: 0 | X39: 0 | Y39: 0 | Z39: 0 | AA39: 0 | AB39: 0 | AC39: =R39 -> 446796 | AD39: 38752456 | AE39: Not Due | AF39: 89064 | AG39: 46177 | AH39: 46180 | AJ39: =M39 -> INR | AK39: 1 | AL39: =N39*AK39 -> 446796 | AM39: =R39-AL39 -> 0 | AN39: =AL39 -> 446796 | AO39: =$AO$19-AH39 -> -68 | AP39: =IF(AO39<0,"Not Due",IF(AO39<366,"Less than 1 year",IF(AO39<731,"1-2 years",IF(AO39<1096,"2-3 years","More than 3 years")))) -> Not Due
A40: GE India Industrial Pvt Ltd - GEITC | B40: GR16 | C40: 2070201000 | D40: Trade Accounts Payable-Subledge | E40: GENPACT INDIA PRIVATE LIMITED A37168 | F40: Non-IBS | G40: Domestic | I40: Opex | J40: B2ZXKA17980 | K40: 100068530 | L40: 46030 | M40: INR | N40: 371736 | O40: 1 | P40: =N40*O40 -> 371736 | Q40: 1 | R40: =N40*Q40 -> 371736 | S40: =R40-P40 -> 0 | T40: Non-MSME | U40: =$U$1-AH40 -> -68 | V40: 0 | W40: 0 | X40: 0 | Y40: 0 | Z40: 0 | AA40: 0 | AB40: 0 | AC40: =R40 -> 371736 | AD40: 38746931 | AE40: Not Due | AF40: 89064 | AG40: 46177 | AH40: 46180 | AJ40: =M40 -> INR | AK40: 1 | AL40: =N40*AK40 -> 371736 | AM40: =R40-AL40 -> 0 | AN40: =AL40 -> 371736 | AO40: =$AO$19-AH40 -> -68 | AP40: =IF(AO40<0,"Not Due",IF(AO40<366,"Less than 1 year",IF(AO40<731,"1-2 years",IF(AO40<1096,"2-3 years","More than 3 years")))) -> Not Due
A41: GE India Industrial Pvt Ltd - GEITC | B41: GR16 | C41: 2070201000 | D41: Trade Accounts Payable-Subledge | E41: GENPACT INDIA PRIVATE LIMITED A37168 | F41: Non-IBS | G41: Domestic | I41: Opex | J41: B2ZXKA17480 | K41: 100067774 | L41: 45974 | M41: INR | N41: 2171110 | O41: 1 | P41: =N41*O41 -> 2171110 | Q41: 1 | R41: =N41*Q41 -> 2171110 | S41: =R41-P41 -> 0 | T41: Non-MSME | U41: =$U$1-AH41 -> -12 | V41: 0 | W41: 0 | X41: 0 | Y41: 0 | Z41: 0 | AA41: 0 | AB41: 0 | AC41: =R41 -> 2171110 | AD41: 38545723 | AE41: Not Due | AF41: 88158 | AG41: 46121 | AH41: 46124 | AJ41: =M41 -> INR | AK41: 1 | AL41: =N41*AK41 -> 2171110 | AM41: =R41-AL41 -> 0 | AN41: =AL41 -> 2171110 | AO41: =$AO$19-AH41 -> -12 | AP41: =IF(AO41<0,"Not Due",IF(AO41<366,"Less than 1 year",IF(AO41<731,"1-2 years",IF(AO41<1096,"2-3 years","More than 3 years")))) -> Not Due
A42: GE India Industrial Pvt Ltd - GEITC | B42: GR16 | C42: 2070201000 | D42: Trade Accounts Payable-Subledge | E42: GENPACT INDIA PRIVATE LIMITED A37168 | F42: Non-IBS | G42: Domestic | I42: Opex | J42: B2ZXKA17449 | K42: 100065083 | L42: 45971 | M42: INR | N42: 905212.8 | O42: 1 | P42: =N42*O42 -> 905212.8 | Q42: 1 | R42: =N42*Q42 -> 905212.8 | S42: =R42-P42 -> 0 | T42: Non-MSME | U42: =$U$1-AH42 -> -9 | V42: 0 | W42: 0 | X42: 0 | Y42: 0 | Z42: 0 | AA42: 0 | AB42: 0 | AC42: =R42 -> 905212.8 | AD42: 38513973 | AE42: Not Due | AF42: 88097 | AG42: 46118 | AH42: 46121 | AJ42: =M42 -> INR | AK42: 1 | AL42: =N42*AK42 -> 905212.8 | AM42: =R42-AL42 -> 0 | AN42: =AL42 -> 905212.8 | AO42: =$AO$19-AH42 -> -9 | AP42: =IF(AO42<0,"Not Due",IF(AO42<366,"Less than 1 year",IF(AO42<731,"1-2 years",IF(AO42<1096,"2-3 years","More than 3 years")))) -> Not Due
A43: GE India Industrial Pvt Ltd - GEITC | B43: GR16 | C43: 2070201000 | D43: Trade Accounts Payable-Subledge | E43: Wissen Infotech Pvt Ltd A38031 | F43: Non-IBS | G43: Domestic | I43: Opex | J43: WBD/25-26/2925 | K43: 100065403 | L43: 46035 | M43: INR | N43: 348105.6 | O43: 1 | P43: =N43*O43 -> 348105.6 | Q43: 1 | R43: =N43*Q43 -> 348105.6 | S43: =R43-P43 -> 0 | T43: Non-MSME | U43: =$U$1-AH43 -> -43 | V43: 0 | W43: 0 | X43: 0 | Y43: 0 | Z43: 0 | AA43: 0 | AB43: 0 | AC43: =R43 -> 348105.6 | AD43: 38765016 | AE43: Not Due | AF43: 88655 | AG43: 46153 | AH43: 46155 | AJ43: =M43 -> INR | AK43: 1 | AL43: =N43*AK43 -> 348105.6 | AM43: =R43-AL43 -> 0 | AN43: =AL43 -> 348105.6 | AO43: =$AO$19-AH43 -> -43 | AP43: =IF(AO43<0,"Not Due",IF(AO43<366,"Less than 1 year",IF(AO43<731,"1-2 years",IF(AO43<1096,"2-3 years","More than 3 years")))) -> Not Due
A44: GE India Industrial Pvt Ltd - GEITC | B44: GR16 | C44: 2070201000 | D44: Trade Accounts Payable-Subledge | E44: Mrk Water Supply A37976 | F44: Non-IBS | G44: Domestic | I44: Opex | J44: 354 | K44: 100070424 | L44: 46083 | M44: INR | N44: 160417.42 | O44: 1 | P44: =N44*O44 -> 160417.42 | Q44: 1 | R44: =N44*Q44 -> 160417.42 | S44: =R44-P44 -> 0 | T44: Non-MSME | U44: =$U$1-AH44 -> -16 | V44: 0 | W44: 0 | X44: 0 | Y44: 0 | Z44: 0 | AA44: 0 | AB44: 0 | AC44: =R44 -> 160417.42 | AD44: 38976216 | AE44: Not Due | AF44: 88213 | AG44: 46125 | AH44: 46128 | AJ44: =M44 -> INR | AK44: 1 | AL44: =N44*AK44 -> 160417.42 | AM44: =R44-AL44 -> 0 | AN44: =AL44 -> 160417.42 | AO44: =$AO$19-AH44 -> -16 | AP44: =IF(AO44<0,"Not Due",IF(AO44<366,"Less than 1 year",IF(AO44<731,"1-2 years",IF(AO44<1096,"2-3 years","More than 3 years")))) -> Not Due
...

Sheet AP Liability MSME
A1: =Memo!A1 -> 0 | U1: ='SSS Accrual Non MSME'!Y1 -> 46112
A2: =Memo!A2 -> 0
A3: =Memo!A3 -> 0
A5: Work Done
A6: 1. ET has obtained the schedule for AP Liability (MSME).
A7: 2. ET has verified the exchange rate considered for closing payable amount.
A8: 3. ET has recomputed the ageing of invoices payable from due date.
A9: 4. ET has checked the computation of due date and performed 3 way match on sample basis.
A11: Summary
A13: Particulars | B13: Amount
A14: Payable Amount | B14: =R19 -> 51951832
A15: Subsequently Paid | B15: =$AO$19 -> 51958540
A16: Subsequently Paid % | B16: =B15/B14 -> 1.0001291
A18: AP Liability Schedule - MSME | AK18: DHS Testing
R19: =SUM(R21:R412) -> 51951832 | S19: =SUM(S20:S97) -> 0 | V19: =SUM(V21:V412) -> -8665.5 | W19: =SUM(W21:W412) -> 41029 | X19: =SUM(X21:X412) -> 0 | Y19: =SUM(Y21:Y412) -> 0 | Z19: =SUM(Z21:Z412) -> 0 | AA19: =SUM(AA21:AA412) -> 0 | AB19: =SUM(AB21:AB412) -> 0 | AC19: =SUM(AC21:AC412) -> 51919468 | AM19: =SUM(AM21:AM412) -> 51951832 | AN19: =SUM(AN21:AN412) -> 0 | AO19: =SUM(AO20:AO970) -> 51958540 | AP19: 46112
A20: Division | B20: Company Code | C20: Account Code | D20: Account Description | E20: Vendor Name | F20: Related Party | G20: Foreign / Domestic | H20: Unique | I20: Nature (Capital/Trade) | J20: Invoice Number | K20: PO Number | L20: Invoice Date | M20: Currency | N20: Invoice Original Amount | O20: MOR Rate | P20: Invoice Amount INR | Q20: RBI Rate | R20: Amount as per RBI | S20: FX_Diff | T20: MSMED | U20: Ageing | V20: 0-30 days | W20: 30-60 days | X20: 60-90 days | Y20: 90-120 days | Z20: 120-180 days | AA20: 180 Days-3 year | AB20: >3 Years | AC20: Not Due | AD20: Invoice Id | AE20: Reson for more than 180 days/debit balances/No GE entity payables | AF20: Subsequent payment Doc # | AG20: Date of subsequent payment | AH20: Due date | AK20: Currency | AL20: Exchange Rate | AM20: Amount in INR | AN20: Difference | AO20: Subsequently Paid | AP20: No. of Days | AQ20: Ageing Bracket
A21: GE India Industrial Pvt Ltd - GEITC | B21: GR16 | C21: 2070201000 | D21: Trade Accounts Payable-Subledge | E21: Eta Engineers Bangalore Private Limited A37548 | F21: Non-IBS | G21: Domestic | I21: Capex | J21: 339/HO/2025-26 | K21: 100069162 | L21: 46073 | M21: INR | N21: 105826.8 | O21: 1 | P21: =N21*O21 -> 105826.8 | Q21: 1 | R21: =N21*Q21 -> 105826.8 | S21: =R21-P21 -> 0 | T21: Small | U21: =$U$1-AH21 -> -6 | V21: 0 | W21: 0 | X21: 0 | Y21: 0 | Z21: 0 | AA21: 0 | AB21: 0 | AC21: =R21 -> 105826.8 | AD21: 38965277 | AE21: Not Due | AF21: 88061 | AG21: 46115 | AH21: 46118 | AK21: INR | AL21: 1 | AM21: =N21*AL21 -> 105826.8 | AN21: =R21-AM21 -> 0 | AO21: =AM21 -> 105826.8 | AP21: =$AP$19-AH21 -> -6 | AQ21: =IF(AP21<0,"Not Due",IF(AP21<366,"Less than 1 year",IF(AP21<731,"1-2 years",IF(AP21<1096,"2-3 years","More than 3 years")))) -> Not Due
A22: GE India Industrial Pvt Ltd - GEITC | B22: GR16 | C22: 2070201000 | D22: Trade Accounts Payable-Subledge | E22: Shobha Electricals A37602 | F22: Non-IBS | G22: Domestic | I22: Opex | J22: SER/448/25-26 | K22: 100069853 | L22: 46083 | M22: INR | N22: 17980 | O22: 1 | P22: =N22*O22 -> 17980 | Q22: 1 | R22: =N22*Q22 -> 17980 | S22: =R22-P22 -> 0 | T22: Small | U22: =$U$1-AH22 -> -16 | V22: 0 | W22: 0 | X22: 0 | Y22: 0 | Z22: 0 | AA22: 0 | AB22: 0 | AC22: =R22 -> 17980 | AD22: 38976052 | AE22: Not Due | AF22: 88201 | AG22: 46125 | AH22: 46128 | AK22: INR | AL22: 1 | AM22: =N22*AL22 -> 17980 | AN22: =R22-AM22 -> 0 | AO22: =AM22 -> 17980 | AP22: =$AP$19-AH22 -> -16 | AQ22: =IF(AP22<0,"Not Due",IF(AP22<366,"Less than 1 year",IF(AP22<731,"1-2 years",IF(AP22<1096,"2-3 years","More than 3 years")))) -> Not Due
A23: GE India Industrial Pvt Ltd - GEITC | B23: GR16 | C23: 2070201000 | D23: Trade Accounts Payable-Subledge | E23: Pro Team Solutions Private Limited A37469 | F23: Non-IBS | G23: Domestic | I23: Opex | J23: PTSB/25-26/4065 | K23: 100067691 | L23: 46082 | M23: INR | N23: 199263.51 | O23: 1 | P23: =N23*O23 -> 199263.51 | Q23: 1 | R23: =N23*Q23 -> 199263.51 | S23: =R23-P23 -> 0 | T23: Small | U23: =$U$1-AH23 -> -15 | V23: 0 | W23: 0 | X23: 0 | Y23: 0 | Z23: 0 | AA23: 0 | AB23: 0 | AC23: =R23 -> 199263.51 | AD23: 38964837 | AE23: Not Due | AF23: 88194 | AG23: 46125 | AH23: 46127 | AK23: INR | AL23: 1 | AM23: =N23*AL23 -> 199263.51 | AN23: =R23-AM23 -> 0 | AO23: =AM23 -> 199263.51 | AP23: =$AP$19-AH23 -> -15 | AQ23: =IF(AP23<0,"Not Due",IF(AP23<366,"Less than 1 year",IF(AP23<731,"1-2 years",IF(AP23<1096,"2-3 years","More than 3 years")))) -> Not Due
A24: GE India Industrial Pvt Ltd - GEITC | B24: GR16 | C24: 2070201000 | D24: Trade Accounts Payable-Subledge | E24: Sri Lakshmi Venkateshwara Prasanna A38498 | F24: Non-IBS | G24: Domestic | I24: Opex | J24: 1977/2026-2027 | K24: 100068172 | L24: 46083 | M24: INR | N24: 62129.6 | O24: 1 | P24: =N24*O24 -> 62129.6 | Q24: 1 | R24: =N24*Q24 -> 62129.6 | S24: =R24-P24 -> 0 | T24: Micro | U24: =$U$1-AH24 -> -16 | V24: 0 | W24: 0 | X24: 0 | Y24: 0 | Z24: 0 | AA24: 0 | AB24: 0 | AC24: =R24 -> 62129.6 | AD24: 38956575 | AE24: Not Due | AF24: 88220 | AG24: 46125 | AH24: 46128 | AK24: INR | AL24: 1 | AM24: =N24*AL24 -> 62129.6 | AN24: =R24-AM24 -> 0 | AO24: =AM24 -> 62129.6 | AP24: =$AP$19-AH24 -> -16 | AQ24: =IF(AP24<0,"Not Due",IF(AP24<366,"Less than 1 year",IF(AP24<731,"1-2 years",IF(AP24<1096,"2-3 years","More than 3 years")))) -> Not Due
A25: GE India Industrial Pvt Ltd - GEITC | B25: GR16 | C25: 2070201000 | D25: Trade Accounts Payable-Subledge | E25: Shobha Electricals A37602 | F25: Non-IBS | G25: Domestic | I25: Capex | J25: SER/453/25-26 | K25: 100068779 | L25: 46083 | M25: INR | N25: 52287.5 | O25: 1 | P25: =N25*O25 -> 52287.5 | Q25: 1 | R25: =N25*Q25 -> 52287.5 | S25: =R25-P25 -> 0 | T25: Small | U25: =$U$1-AH25 -> -16 | V25: 0 | W25: 0 | X25: 0 | Y25: 0 | Z25: 0 | AA25: 0 | AB25: 0 | AC25: =R25 -> 52287.5 | AD25: 38977124 | AE25: Not Due | AF25: 88201 | AG25: 46125 | AH25: 46128 | AK25: INR | AL25: 1 | AM25: =N25*AL25 -> 52287.5 | AN25: =R25-AM25 -> 0 | AO25: =AM25 -> 52287.5 | AP25: =$AP$19-AH25 -> -16 | AQ25: =IF(AP25<0,"Not Due",IF(AP25<366,"Less than 1 year",IF(AP25<731,"1-2 years",IF(AP25<1096,"2-3 years","More than 3 years")))) -> Not Due
A26: GE India Industrial Pvt Ltd - GEITC | B26: GR16 | C26: 2070201000 | D26: Trade Accounts Payable-Subledge | E26: Juice Junction A38216 | F26: Non-IBS | G26: Domestic | I26: Opex | J26: JJ/2025-26/277 | K26: 100066527 | L26: 46075 | M26: INR | N26: 9620.2 | O26: 1 | P26: =N26*O26 -> 9620.2 | Q26: 1 | R26: =N26*Q26 -> 9620.2 | S26: =R26-P26 -> 0 | T26: Small | U26: =$U$1-AH26 -> -8 | V26: 0 | W26: 0 | X26: 0 | Y26: 0 | Z26: 0 | AA26: 0 | AB26: 0 | AC26: =R26 -> 9620.2 | AD26: 38956680 | AE26: Not Due | AF26: 88083 | AG26: 46118 | AH26: 46120 | AK26: INR | AL26: 1 | AM26: =N26*AL26 -> 9620.2 | AN26: =R26-AM26 -> 0 | AO26: =AM26 -> 9620.2 | AP26: =$AP$19-AH26 -> -8 | AQ26: =IF(AP26<0,"Not Due",IF(AP26<366,"Less than 1 year",IF(AP26<731,"1-2 years",IF(AP26<1096,"2-3 years","More than 3 years")))) -> Not Due
A27: GE India Industrial Pvt Ltd - GEITC | B27: GR16 | C27: 2070201000 | D27: Trade Accounts Payable-Subledge | E27: Karnataka Kleening Korporation A38055 | F27: Non-IBS | G27: Domestic | I27: Opex | J27: 511/25-26 | K27: 100070800 | L27: 46069 | M27: INR | N27: 73731.92 | O27: 1 | P27: =N27*O27 -> 73731.92 | Q27: 1 | R27: =N27*Q27 -> 73731.92 | S27: =R27-P27 -> 0 | T27: Small | U27: =$U$1-AH27 -> -2 | V27: 0 | W27: 0 | X27: 0 | Y27: 0 | Z27: 0 | AA27: 0 | AB27: 0 | AC27: =R27 -> 73731.92 | AD27: 38921523 | AE27: Not Due | AF27: 88025 | AG27: 46113 | AH27: 46114 | AK27: INR | AL27: 1 | AM27: =N27*AL27 -> 73731.92 | AN27: =R27-AM27 -> 0 | AO27: =AM27 -> 73731.92 | AP27: =$AP$19-AH27 -> -2 | AQ27: =IF(AP27<0,"Not Due",IF(AP27<366,"Less than 1 year",IF(AP27<731,"1-2 years",IF(AP27<1096,"2-3 years","More than 3 years")))) -> Not Due
A28: GE India Industrial Pvt Ltd - GEITC | B28: GR16 | C28: 2070201000 | D28: Trade Accounts Payable-Subledge | E28: Alpha Lab Solutions A38403 | F28: Non-IBS | G28: Domestic | I28: Opex | J28: 135/2025-26 | K28: 100070770 | L28: 46085 | M28: INR | N28: 137026.92 | O28: 1 | P28: =N28*O28 -> 137026.92 | Q28: 1 | R28: =N28*Q28 -> 137026.92 | S28: =R28-P28 -> 0 | T28: Micro | U28: =$U$1-AH28 -> -18 | V28: 0 | W28: 0 | X28: 0 | Y28: 0 | Z28: 0 | AA28: 0 | AB28: 0 | AC28: =R28 -> 137026.92 | AD28: 39012044 | AE28: Not Due | AF28: 88285 | AG28: 46127 | AH28: 46130 | AK28: INR | AL28: 1 | AM28: =N28*AL28 -> 137026.92 | AN28: =R28-AM28 -> 0 | AO28: =AM28 -> 137026.92 | AP28: =$AP$19-AH28 -> -18 | AQ28: =IF(AP28<0,"Not Due",IF(AP28<366,"Less than 1 year",IF(AP28<731,"1-2 years",IF(AP28<1096,"2-3 years","More than 3 years")))) -> Not Due
A29: GE India Industrial Pvt Ltd - GEITC | B29: GR16 | C29: 2070201000 | D29: Trade Accounts Payable-Subledge | E29: Eta Engineers Bangalore Private Limited A37548 | F29: Non-IBS | G29: Domestic | I29: Opex | J29: 358/HO/2025-26 | K29: 100070668 | L29: 46087 | M29: INR | N29: 28001.25 | O29: 1 | P29: =N29*O29 -> 28001.25 | Q29: 1 | R29: =N29*Q29 -> 28001.25 | S29: =R29-P29 -> 0 | T29: Small | U29: =$U$1-AH29 -> -20 | V29: 0 | W29: 0 | X29: 0 | Y29: 0 | Z29: 0 | AA29: 0 | AB29: 0 | AC29: =R29 -> 28001.25 | AD29: 39017906 | AE29: Not Due | AF29: 88311 | AG29: 46129 | AH29: 46132 | AK29: INR | AL29: 1 | AM29: =N29*AL29 -> 28001.25 | AN29: =R29-AM29 -> 0 | AO29: =AM29 -> 28001.25 | AP29: =$AP$19-AH29 -> -20 | AQ29: =IF(AP29<0,"Not Due",IF(AP29<366,"Less than 1 year",IF(AP29<731,"1-2 years",IF(AP29<1096,"2-3 years","More than 3 years")))) -> Not Due
A30: GE India Industrial Pvt Ltd - GEITC | B30: GR16 | C30: 2070201000 | D30: Trade Accounts Payable-Subledge | E30: Mobiveil Technologies India Private Limited A38750 | F30: Non-IBS | G30: Domestic | I30: Opex | J30: MOBBLR25260030 | K30: 100070657 | L30: 46093 | M30: INR | N30: 194400 | O30: 1 | P30: =N30*O30 -> 194400 | Q30: 1 | R30: =N30*Q30 -> 194400 | S30: =R30-P30 -> 0 | T30: Small | U30: =$U$1-AH30 -> -11 | V30: 0 | W30: 0 | X30: 0 | Y30: 0 | Z30: 0 | AA30: 0 | AB30: 0 | AC30: =R30 -> 194400 | AD30: 39018596 | AE30: Not Due | AF30: 88141 | AG30: 46120 | AH30: 46123 | AK30: INR | AL30: 1 | AM30: =N30*AL30 -> 194400 | AN30: =R30-AM30 -> 0 | AO30: =AM30 -> 194400 | AP30: =$AP$19-AH30 -> -11 | AQ30: =IF(AP30<0,"Not Due",IF(AP30<366,"Less than 1 year",IF(AP30<731,"1-2 years",IF(AP30<1096,"2-3 years","More than 3 years")))) -> Not Due
A31: GE India Industrial Pvt Ltd - GEITC | B31: GR16 | C31: 2070201000 | D31: Trade Accounts Payable-Subledge | E31: V.K. Technologies and Services A38107 | F31: Non-IBS | G31: Domestic | I31: Opex | J31: VKTS/11049/25-26 | K31: 100070677 | L31: 46091 | M31: INR | N31: 64137.6 | O31: 1 | P31: =N31*O31 -> 64137.6 | Q31: 1 | R31: =N31*Q31 -> 64137.6 | S31: =R31-P31 -> 0 | T31: Micro | U31: =$U$1-AH31 -> -9 | V31: 0 | W31: 0 | X31: 0 | Y31: 0 | Z31: 0 | AA31: 0 | AB31: 0 | AC31: =R31 -> 64137.6 | AD31: 38999690 | AE31: Not Due | AF31: 88078 | AG31: 46118 | AH31: 46121 | AK31: INR | AL31: 1 | AM31: =N31*AL31 -> 64137.6 | AN31: =R31-AM31 -> 0 | AO31: =AM31 -> 64137.6 | AP31: =$AP$19-AH31 -> -9 | AQ31: =IF(AP31<0,"Not Due",IF(AP31<366,"Less than 1 year",IF(AP31<731,"1-2 years",IF(AP31<1096,"2-3 years","More than 3 years")))) -> Not Due
A32: GE India Industrial Pvt Ltd - GEITC | B32: GR16 | C32: 2070201000 | D32: Trade Accounts Payable-Subledge | E32: Amazing Blooms A38045 | F32: Non-IBS | G32: Domestic | I32: Opex | J32: 1085 | K32: 100070311 | L32: 46085 | M32: INR | N32: 250778.08 | O32: 1 | P32: =N32*O32 -> 250778.08 | Q32: 1 | R32: =N32*Q32 -> 250778.08 | S32: =R32-P32 -> 0 | T32: Small | U32: =$U$1-AH32 -> -18 | V32: 0 | W32: 0 | X32: 0 | Y32: 0 | Z32: 0 | AA32: 0 | AB32: 0 | AC32: =R32 -> 250778.08 | AD32: 38978551 | AE32: Not Due | AF32: 88276 | AG32: 46127 | AH32: 46130 | AK32: INR | AL32: 1 | AM32: =N32*AL32 -> 250778.08 | AN32: =R32-AM32 -> 0 | AO32: =AM32 -> 250778.08 | AP32: =$AP$19-AH32 -> -18 | AQ32: =IF(AP32<0,"Not Due",IF(AP32<366,"Less than 1 year",IF(AP32<731,"1-2 years",IF(AP32<1096,"2-3 years","More than 3 years")))) -> Not Due
A33: GE India Industrial Pvt Ltd - GEITC | B33: GR16 | C33: 2070201000 | D33: Trade Accounts Payable-Subledge | E33: Vinolya Services Pvt Ltd. A38997 | F33: Non-IBS | G33: Domestic | I33: Opex | J33: 13643/25 | K33: 100070312 | L33: 46082 | M33: INR | N33: 48192.1 | O33: 1 | P33: =N33*O33 -> 48192.1 | Q33: 1 | R33: =N33*Q33 -> 48192.1 | S33: =R33-P33 -> 0 | T33: Small | U33: =$U$1-AH33 -> -15 | V33: 0 | W33: 0 | X33: 0 | Y33: 0 | Z33: 0 | AA33: 0 | AB33: 0 | AC33: =R33 -> 48192.1 | AD33: 38956574 | AE33: Not Due | AF33: 88226 | AG33: 46125 | AH33: 46127 | AK33: INR | AL33: 1 | AM33: =N33*AL33 -> 48192.1 | AN33: =R33-AM33 -> 0 | AO33: =AM33 -> 48192.1 | AP33: =$AP$19-AH33 -> -15 | AQ33: =IF(AP33<0,"Not Due",IF(AP33<366,"Less than 1 year",IF(AP33<731,"1-2 years",IF(AP33<1096,"2-3 years","More than 3 years")))) -> Not Due
A34: GE India Industrial Pvt Ltd - GEITC | B34: GR16 | C34: 2070201000 | D34: Trade Accounts Payable-Subledge | E34: Karnataka Kleening Korporation A38055 | F34: Non-IBS | G34: Domestic | I34: Opex | J34: 513/25-26 | K34: 100070794 | L34: 46069 | M34: INR | N34: 71922.32 | O34: 1 | P34: =N34*O34 -> 71922.32 | Q34: 1 | R34: =N34*Q34 -> 71922.32 | S34: =R34-P34 -> 0 | T34: Small | U34: =$U$1-AH34 -> -2 | V34: 0 | W34: 0 | X34: 0 | Y34: 0 | Z34: 0 | AA34: 0 | AB34: 0 | AC34: =R34 -> 71922.32 | AD34: 38915680 | AE34: Not Due | AF34: 88025 | AG34: 46113 | AH34: 46114 | AK34: INR | AL34: 1 | AM34: =N34*AL34 -> 71922.32 | AN34: =R34-AM34 -> 0 | AO34: =AM34 -> 71922.32 | AP34: =$AP$19-AH34 -> -2 | AQ34: =IF(AP34<0,"Not Due",IF(AP34<366,"Less than 1 year",IF(AP34<731,"1-2 years",IF(AP34<1096,"2-3 years","More than 3 years")))) -> Not Due
A35: GE India Industrial Pvt Ltd - GEITC | B35: GR16 | C35: 2070201000 | D35: Trade Accounts Payable-Subledge | E35: Cool India A39008 | F35: Non-IBS | G35: Domestic | I35: Opex | J35: CI/25-26/241 | K35: 100067488 | L35: 46088 | M35: INR | N35: 489741.8 | O35: 1 | P35: =N35*O35 -> 489741.8 | Q35: 1 | R35: =N35*Q35 -> 489741.8 | S35: =R35-P35 -> 0 | T35: Micro | U35: =$U$1-AH35 -> -21 | V35: 0 | W35: 0 | X35: 0 | Y35: 0 | Z35: 0 | AA35: 0 | AB35: 0 | AC35: =R35 -> 489741.8 | AD35: 39018010 | AE35: Not Due | AF35: 88355 | AG35: 46132 | AH35: 46133 | AK35: INR | AL35: 1 | AM35: =N35*AL35 -> 489741.8 | AN35: =R35-AM35 -> 0 | AO35: =AM35 -> 489741.8 | AP35: =$AP$19-AH35 -> -21 | AQ35: =IF(AP35<0,"Not Due",IF(AP35<366,"Less than 1 year",IF(AP35<731,"1-2 years",IF(AP35<1096,"2-3 years","More than 3 years")))) -> Not Due
A36: GE India Industrial Pvt Ltd - GEITC | B36: GR16 | C36: 2070201000 | D36: Trade Accounts Payable-Subledge | E36: Pro Team Solutions Private Limited A37469 | F36: Non-IBS | G36: Domestic | I36: Opex | J36: PTSB/25-26/4069 | K36: 100066019 | L36: 46082 | M36: INR | N36: 60111 | O36: 1 | P36: =N36*O36 -> 60111 | Q36: 1 | R36: =N36*Q36 -> 60111 | S36: =R36-P36 -> 0 | T36: Small | U36: =$U$1-AH36 -> -15 | V36: 0 | W36: 0 | X36: 0 | Y36: 0 | Z36: 0 | AA36: 0 | AB36: 0 | AC36: =R36 -> 60111 | AD36: 38977101 | AE36: Not Due | AF36: 88194 | AG36: 46125 | AH36: 46127 | AK36: INR | AL36: 1 | AM36: =N36*AL36 -> 60111 | AN36: =R36-AM36 -> 0 | AO36: =AM36 -> 60111 | AP36: =$AP$19-AH36 -> -15 | AQ36: =IF(AP36<0,"Not Due",IF(AP36<366,"Less than 1 year",IF(AP36<731,"1-2 years",IF(AP36<1096,"2-3 years","More than 3 years")))) -> Not Due
A37: GE India Industrial Pvt Ltd - GEITC | B37: GR16 | C37: 2070201000 | D37: Trade Accounts Payable-Subledge | E37: Altair Engineering India Pvt LTD A37670 | F37: Non-IBS | G37: Domestic | I37: Opex | J37: INVALKA-04049 | K37: 100066402 | L37: 45930 | M37: INR | N37: 2384640 | O37: 1 | P37: =N37*O37 -> 2384640 | Q37: 1 | R37: =N37*Q37 -> 2384640 | S37: =R37-P37 -> 0 | T37: Medium | U37: =$U$1-AH37 -> -16 | V37: 0 | W37: 0 | X37: 0 | Y37: 0 | Z37: 0 | AA37: 0 | AB37: 0 | AC37: =R37 -> 2384640 | AD37: 39012917 | AE37: Not Due | AF37: 88204 | AG37: 46125 | AH37: 46128 | AK37: INR | AL37: 1 | AM37: =N37*AL37 -> 2384640 | AN37: =R37-AM37 -> 0 | AO37: =AM37 -> 2384640 | AP37: =$AP$19-AH37 -> -16 | AQ37: =IF(AP37<0,"Not Due",IF(AP37<366,"Less than 1 year",IF(AP37<731,"1-2 years",IF(AP37<1096,"2-3 years","More than 3 years")))) -> Not Due
A38: GE India Industrial Pvt Ltd - GEITC | B38: GR16 | C38: 2070201000 | D38: Trade Accounts Payable-Subledge | E38: Juice Junction A38216 | F38: Non-IBS | G38: Domestic | I38: Opex | J38: JJ/2025-26/301 | K38: 100066527 | L38: 46100 | M38: INR | N38: 8240 | O38: 1 | P38: =N38*O38 -> 8240 | Q38: 1 | R38: =N38*Q38 -> 8240 | S38: =R38-P38 -> 0 | T38: Small | U38: =$U$1-AH38 -> -33 | V38: 0 | W38: 0 | X38: 0 | Y38: 0 | Z38: 0 | AA38: 0 | AB38: 0 | AC38: =R38 -> 8240 | AD38: 39036215 | AE38: Not Due | AF38: 88523 | AG38: 46143 | AH38: 46145 | AK38: INR | AL38: 1 | AM38: =N38*AL38 -> 8240 | AN38: =R38-AM38 -> 0 | AO38: =AM38 -> 8240 | AP38: =$AP$19-AH38 -> -33 | AQ38: =IF(AP38<0,"Not Due",IF(AP38<366,"Less than 1 year",IF(AP38<731,"1-2 years",IF(AP38<1096,"2-3 years","More than 3 years")))) -> Not Due
A39: GE India Industrial Pvt Ltd - GEITC | B39: GR16 | C39: 2070201000 | D39: Trade Accounts Payable-Subledge | E39: Lakshya Tech India Pvt LTD A37629 | F39: Non-IBS | G39: Domestic | I39: Opex | J39: M1537/25-26 | K39: 100070644 | L39: 46085 | M39: INR | N39: 446322.24 | O39: 1 | P39: =N39*O39 -> 446322.24 | Q39: 1 | R39: =N39*Q39 -> 446322.24 | S39: =R39-P39 -> 0 | T39: Small | U39: =$U$1-AH39 -> -3 | V39: 0 | W39: 0 | X39: 0 | Y39: 0 | Z39: 0 | AA39: 0 | AB39: 0 | AC39: =R39 -> 446322.24 | AD39: 38981852 | AE39: Not Due | AF39: 88013 | AG39: 46113 | AH39: 46115 | AK39: INR | AL39: 1 | AM39: =N39*AL39 -> 446322.24 | AN39: =R39-AM39 -> 0 | AO39: =AM39 -> 446322.24 | AP39: =$AP$19-AH39 -> -3 | AQ39: =IF(AP39<0,"Not Due",IF(AP39<366,"Less than 1 year",IF(AP39<731,"1-2 years",IF(AP39<1096,"2-3 years","More than 3 years")))) -> Not Due
A40: GE India Industrial Pvt Ltd - GEITC | B40: GR16 | C40: 2070201000 | D40: Trade Accounts Payable-Subledge | E40: Sheen Electroplaters Private Limited A38710 | F40: Non-IBS | G40: Domestic | I40: Opex | J40: 25-26/08745 | K40: 100070724 | L40: 46088 | M40: INR | N40: 111179.7 | O40: 1 | P40: =N40*O40 -> 111179.7 | Q40: 1 | R40: =N40*Q40 -> 111179.7 | S40: =R40-P40 -> 0 | T40: Small | U40: =$U$1-AH40 -> -21 | V40: 0 | W40: 0 | X40: 0 | Y40: 0 | Z40: 0 | AA40: 0 | AB40: 0 | AC40: =R40 -> 111179.7 | AD40: 38993167 | AE40: Not Due | AF40: 88345 | AG40: 46132 | AH40: 46133 | AK40: INR | AL40: 1 | AM40: =N40*AL40 -> 111179.7 | AN40: =R40-AM40 -> 0 | AO40: =AM40 -> 111179.7 | AP40: =$AP$19-AH40 -> -21 | AQ40: =IF(AP40<0,"Not Due",IF(AP40<366,"Less than 1 year",IF(AP40<731,"1-2 years",IF(AP40<1096,"2-3 years","More than 3 years")))) -> Not Due
A41: GE India Industrial Pvt Ltd - GEITC | B41: GR16 | C41: 2070201000 | D41: Trade Accounts Payable-Subledge | E41: BK INFRASYS PRIVATE LIMITED A39017 | F41: Non-IBS | G41: Domestic | I41: Opex | J41: 122/2025-26 | K41: 100066515 | L41: 46077 | M41: INR | N41: 37973.76 | O41: 1 | P41: =N41*O41 -> 37973.76 | Q41: 1 | R41: =N41*Q41 -> 37973.76 | S41: =R41-P41 -> 0 | T41: Small | U41: =$U$1-AH41 -> -10 | V41: 0 | W41: 0 | X41: 0 | Y41: 0 | Z41: 0 | AA41: 0 | AB41: 0 | AC41: =R41 -> 37973.76 | AD41: 38981682 | AE41: Not Due | AF41: 88119 | AG41: 46119 | AH41: 46122 | AK41: INR | AL41: 1 | AM41: =N41*AL41 -> 37973.76 | AN41: =R41-AM41 -> 0 | AO41: =AM41 -> 37973.76 | AP41: =$AP$19-AH41 -> -10 | AQ41: =IF(AP41<0,"Not Due",IF(AP41<366,"Less than 1 year",IF(AP41<731,"1-2 years",IF(AP41<1096,"2-3 years","More than 3 years")))) -> Not Due
A42: GE India Industrial Pvt Ltd - GEITC | B42: GR16 | C42: 2070201000 | D42: Trade Accounts Payable-Subledge | E42: S.S. Manpower Services Pvt LTD A37638 | F42: Non-IBS | G42: Domestic | I42: Opex | J42: SSMS/2025-26/353 | K42: 100068772 | L42: 46085 | M42: INR | N42: 55726.2 | O42: 1 | P42: =N42*O42 -> 55726.2 | Q42: 1 | R42: =N42*Q42 -> 55726.2 | S42: =R42-P42 -> 0 | T42: Micro | U42: =$U$1-AH42 -> -18 | V42: 0 | W42: 0 | X42: 0 | Y42: 0 | Z42: 0 | AA42: 0 | AB42: 0 | AC42: =R42 -> 55726.2 | AD42: 38983036 | AE42: Not Due | AF42: 88279 | AG42: 46127 | AH42: 46130 | AK42: INR | AL42: 1 | AM42: =N42*AL42 -> 55726.2 | AN42: =R42-AM42 -> 0 | AO42: =AM42 -> 55726.2 | AP42: =$AP$19-AH42 -> -18 | AQ42: =IF(AP42<0,"Not Due",IF(AP42<366,"Less than 1 year",IF(AP42<731,"1-2 years",IF(AP42<1096,"2-3 years","More than 3 years")))) -> Not Due
A43: GE India Industrial Pvt Ltd - GEITC | B43: GR16 | C43: 2070201000 | D43: Trade Accounts Payable-Subledge | E43: Bethur Unique Engineering LLP A38791 | F43: Non-IBS | G43: Domestic | I43: Opex | J43: DS2025666 | K43: 100070364 | L43: 46076 | M43: INR | N43: 15660 | O43: 1 | P43: =N43*O43 -> 15660 | Q43: 1 | R43: =N43*Q43 -> 15660 | S43: =R43-P43 -> 0 | T43: Micro | U43: =$U$1-AH43 -> -9 | V43: 0 | W43: 0 | X43: 0 | Y43: 0 | Z43: 0 | AA43: 0 | AB43: 0 | AC43: =R43 -> 15660 | AD43: 38927080 | AE43: Not Due | AF43: 88092 | AG43: 46118 | AH43: 46121 | AK43: INR | AL43: 1 | AM43: =N43*AL43 -> 15660 | AN43: =R43-AM43 -> 0 | AO43: =AM43 -> 15660 | AP43: =$AP$19-AH43 -> -9 | AQ43: =IF(AP43<0,"Not Due",IF(AP43<366,"Less than 1 year",IF(AP43<731,"1-2 years",IF(AP43<1096,"2-3 years","More than 3 years")))) -> Not Due
A44: GE India Industrial Pvt Ltd - GEITC | B44: GR16 | C44: 2070201000 | D44: Trade Accounts Payable-Subledge | E44: Equipment Fabricators A37538 | F44: Non-IBS | G44: Domestic | I44: Opex | J44: EF435/2025-26 | K44: 100070689 | L44: 46078 | M44: INR | N44: 22263.06 | O44: 1 | P44: =N44*O44 -> 22263.06 | Q44: 1 | R44: =N44*Q44 -> 22263.06 | S44: =R44-P44 -> 0 | T44: Small | U44: =$U$1-AH44 -> -11 | V44: 0 | W44: 0 | X44: 0 | Y44: 0 | Z44: 0 | AA44: 0 | AB44: 0 | AC44: =R44 -> 22263.06 | AD44: 38956621 | AE44: Not Due | AF44: 88127 | AG44: 46120 | AH44: 46123 | AK44: INR | AL44: 1 | AM44: =N44*AL44 -> 22263.06 | AN44: =R44-AM44 -> 0 | AO44: =AM44 -> 22263.06 | AP44: =$AP$19-AH44 -> -11 | AQ44: =IF(AP44<0,"Not Due",IF(AP44<366,"Less than 1 year",IF(AP44<731,"1-2 years",IF(AP44<1096,"2-3 years","More than 3 years")))) -> Not Due
...

Sheet SSS Accrual Non MSME
A1: =Memo!A1 -> 0 | Y1: 46112
A2: =Memo!A2 -> 0
A3: =Memo!A3 -> 0
A5: Work Done
A6: 1. ET has obtained the schedule for SSS Accrual (Non-MSME).
A7: 2. ET has verified the exchange rate considered for closing payable amount.
A8: 3. ET has recomputed the ageing of invoices payable from due date.
A9: 4. ET has checked the computation of due date and performed 3 way match on sample basis.
A11: Summary
A13: Particulars | B13: Amount
A14: Payable Amount | B14: =$AK$19 -> 1.5423263e+08
A15: Subsequently Paid | B15: =$AM$19 -> 1.536038e+08
A16: Subsequently Paid % | B16: =B15/B14 -> 0.99592281
A18: SSS Accrual Schedule - Non MSME | AI18: DHS Testing
N19: =SUM(N20:N5300) -> 1.5423263e+08 | AA19: =SUM(AA21:AA226) -> 17001164 | AB19: =SUM(AB21:AB226) -> 1985.5 | AC19: =SUM(AC21:AC226) -> 0 | AD19: =SUM(AD21:AD226) -> 0 | AE19: =SUM(AE21:AE226) -> 418599.18 | AF19: =SUM(AF21:AF226) -> 0 | AG19: =SUM(AG21:AG226) -> 1.3681088e+08 | AK19: =SUM(AK20:AK530) -> 1.5423263e+08 | AL19: =SUM(AL20:AL530) -> 0 | AM19: =SUM(AM20:AM530) -> 1.536038e+08 | AN19: 46112
A20: VENDOR_NAME | B20: LINE_DESC | C20: PO_NUM | D20: COST CENTER | E20: CURRENCY_CODE | F20: Entered Net | G20: MOR Rate | H20: RBI Rate | I20: Functional Amount in INR | J20: Amount as per RBI rate | K20: FX Impact | L20: TDS | M20: Net Amount In INR | N20: Net Amount as Per RBI | O20: Opex/Capex | P20: MSMED | Q20: Supplier# | R20: PO Description | S20: Invoice# | T20: Invoice accounted date | U20: Invoice date | V20: Subsequent payment Doc # | W20: Date of subsequent payment | X20: Remarks | Y20: Due Date | Z20: Ageing | AA20: 0-30 days | AB20: 30-60 days | AC20: 60- 90 days | AD20: 90-180 days | AE20: 180- 365 days | AF20: > 365 days | AG20: Not Due | AI20: Currency | AJ20: Exchange Rate | AK20: Amount in INR | AL20: Difference | AM20: Subsequently Paid | AN20: No. of Days | AO20: Ageing Bracket
A21: NETZSCH GERATEBAU GMBH | B21: Project#271209,Task#1001,INV#,Barcode#,Po#100070970,PoLine#2,VendorName-NETZSCH GERATEBAU GMBH,Desc-Supply of sample crucible - Al2O3 for DSC instrume,PT#2712091001 | C21: 100070970 | D21: GRAS01 | E21: EUR | F21: 1170 | G21: 108.38462 | H21: 109.0064 | I21: =F21*G21 -> 126810.01 | J21: =F21*H21 -> 127537.49 | K21: =J21-I21 -> 727.47726 | L21: 0 | M21: =I21-L21 -> 126810.01 | N21: =J21-L21 -> 127537.49 | O21: Opex | P21: Non-MSME | Q21: A39046 | R21: Supply of sample crucible - Al2O3 for DSC instrument. Size: outer bottom Ø 6.8 mm, 85 µl . | S21: 14298263 | U21: 46099 | V21: Adjusted against advance | X21: Adjusted against advance | Y21: 46125 | Z21: =$Y$1-Y21 -> -13 | AA21: 0 | AB21: 0 | AC21: 0 | AD21: 0 | AE21: 0 | AF21: 0 | AG21: 127537.49 | AI21: =E21 -> EUR | AJ21: 109.0064 | AK21: =F21*AJ21-L21 -> 127537.49 | AL21: =N21-AK21 -> 0 | AM21: =N21 -> 127537.49 | AN21: =$AN$19-Y21 -> -13 | AO21: =IF(AN21<0,"Not Due",IF(AN21<366,"Less than 1 year",IF(AN21<731,"1-2 years",IF(AN21<1096,"2-3 years","More than 3 years")))) -> Not Due
A22: NATIONAL PHARMA CENTRE A38146 | B22: Project#116889,Task#3203,INV#,Barcode#,Po#100071269,PoLine#1,VendorName-NATIONAL PHARMA CENTRE A38146,Desc-Supply of Medicines- Details as per annexure,PT#1168893203 | C22: 100071269 | D22: GC6889 | E22: INR | F22: 23417.18 | G22: 1 | H22: 1 | I22: =F22*G22 -> 23417.18 | J22: =F22*H22 -> 23417.18 | K22: =J22-I22 -> 0 | L22: 23 | M22: =I22-L22 -> 23394.18 | N22: =J22-L22 -> 23394.18 | O22: Opex | P22: Non-MSME | Q22: A38146 | R22: Supply of Medicines- Details as per annexure | S22: NAT00262 | T22: 46125 | U22: 46099 | V22: 88388 | W22: 46134 | Y22: 46129 | Z22: =$Y$1-Y22 -> -17 | AA22: 0 | AB22: 0 | AC22: 0 | AD22: 0 | AE22: 0 | AF22: 0 | AG22: 23394.18 | AI22: =E22 -> INR | AJ22: 1 | AK22: =F22*AJ22-L22 -> 23394.18 | AL22: =N22-AK22 -> 0 | AM22: =N22 -> 23394.18 | AN22: =$AN$19-Y22 -> -17 | AO22: =IF(AN22<0,"Not Due",IF(AN22<366,"Less than 1 year",IF(AN22<731,"1-2 years",IF(AN22<1096,"2-3 years","More than 3 years")))) -> Not Due
A23: INFINITI POWER PRIVATE LIMITED A37094 | B23: Project#117399,Task#3006,INV#,Barcode#,Po#100070904,PoLine#2,VendorName-INFINITI POWER PRIVATE LIMITED A37094,Desc-Supply of IT materials towards Network related wor,PT#1173993006 | C23: 100070904 | D23: GC7399 | E23: INR | F23: 48126 | G23: 1 | H23: 1 | I23: =F23*G23 -> 48126 | J23: =F23*H23 -> 48126 | K23: =J23-I23 -> 0 | L23: 48 | M23: =I23-L23 -> 48078 | N23: =J23-L23 -> 48078 | O23: Opex | P23: Non-MSME | Q23: A37094 | R23: Supply and installation of IT materials for Upgradation of meeting room / cabin in JFWTC. Details as per annexure. | S23: 252900478 | T23: 46083 | U23: 46076 | V23: 88089 | W23: 46118 | Y23: 46121 | Z23: =$Y$1-Y23 -> -9 | AA23: 0 | AB23: 0 | AC23: 0 | AD23: 0 | AE23: 0 | AF23: 0 | AG23: 48078 | AI23: =E23 -> INR | AJ23: 1 | AK23: =F23*AJ23-L23 -> 48078 | AL23: =N23-AK23 -> 0 | AN23: =$AN$19-Y23 -> -9 | AO23: =IF(AN23<0,"Not Due",IF(AN23<366,"Less than 1 year",IF(AN23<731,"1-2 years",IF(AN23<1096,"2-3 years","More than 3 years")))) -> Not Due
A24: INFINITI POWER PRIVATE LIMITED A37094 | B24: Project#117399,Task#3006,INV#,Barcode#,Po#100070904,PoLine#3,VendorName-INFINITI POWER PRIVATE LIMITED A37094,Desc-Supply of IT materials towards Network related wor,PT#1173993006 | C24: 100070904 | D24: GC7399 | E24: INR | F24: 1839 | G24: 1 | H24: 1 | I24: =F24*G24 -> 1839 | J24: =F24*H24 -> 1839 | K24: =J24-I24 -> 0 | L24: 2 | M24: =I24-L24 -> 1837 | N24: =J24-L24 -> 1837 | O24: Opex | P24: Non-MSME | Q24: A37094 | R24: Supply and installation of IT materials for Upgradation of meeting room / cabin in JFWTC. Details as per annexure. | S24: 252900478 | T24: 46083 | U24: 46076 | V24: 88089 | W24: 46118 | Y24: 46121 | Z24: =$Y$1-Y24 -> -9 | AA24: 0 | AB24: 0 | AC24: 0 | AD24: 0 | AE24: 0 | AF24: 0 | AG24: 1837 | AI24: =E24 -> INR | AJ24: 1 | AK24: =F24*AJ24-L24 -> 1837 | AL24: =N24-AK24 -> 0 | AN24: =$AN$19-Y24 -> -9 | AO24: =IF(AN24<0,"Not Due",IF(AN24<366,"Less than 1 year",IF(AN24<731,"1-2 years",IF(AN24<1096,"2-3 years","More than 3 years")))) -> Not Due
