Workbook

Sheet Scope
A2: Purpose
A3: To verify lease liability and ROU as at March 31, 2026
A5: Work Done
A7: Assertion | B7: Procedures | C7: Reference
A8: Valuation and Allocation | B8: ET performed the recomputation of new leases started as well as leases terminated during the year on samples extracted using MUS | C8: << Refer tab testing >>
B9: ET verified the depreciation of ROU assets and verified that the same has been computed on the basis of the lease period. | C9: << Refer tab testing >>
B10: ET verified the finance cost on the lease liabilities | C10: << Refer tab testing >>
A11: Existence | B11: ET obtained the executed agreement from the client of the new leases added during the year. | C11: << Refer tab testing >>
B12: ET verified the lease deeds of the leasehold lands and verified whether the same are registered in the name of the Company. | C12: << Refer WP B. CARO Workbook GEIIPL 2026>>
B13: ET obtained the physical verification certificates from the management and analysed the coverage of the physical verification. | C13: << Refer WP B. CARO Workbook GEIIPL 2026>>
A14: Completeness | B14: ET obtained the schedule of rental expenses and verified that they are not to be accounted for as lease. | C14: << Refer workspace Rent >>
A15: Accuracy | B15: ET has verified the lease start date, end date, monthly payment amount as per the agreement. | C15: << Refer tab testing >>
B16: ET performed the recomputation of the lease liability and ROU to ensure the accuracy of the IPE. | C16: << Refer tab testing >>
B17: ET has verified the discount rate used for discounting from the GSEC rates which have been used by the Company. | C17: << Refer tab additions summary >>
A18: Presentation and Disclosure | B18: ET has also reconciled the values appearing in the balance sheet and verified the notes to account with the balance as per Schedule. | C18: << Refer tab Notes to Account >>
B19: ET has ensured that the notes to account are in accordance with the requirements of Ind AS 116. | C19: << Refer tab Notes to Account >>
A22: Observation
A23: None
A26: Conclusion
A27: No material misstatements identified

Sheet Notes to Account
A1: =Scope!#REF! -> #REF!
A2: =Scope!#REF! -> #REF!
A3: =Scope!#REF! -> #REF!
A5: Purpose
A6: To verify the amounts disclosed in notes to account as on March 31, 2026
A8: Note 4.4. Right-of-use assets | F8: (Amount in Rs. Lakhs)
I9: << As per Schedule >> | T9: << Difference >>
A10: Particulars | B10: Buildings | C10: Vehicles | D10: Equipments | E10: IT Equipments | F10: Land | G10: Total | I10: Buildings | J10: Vehicles | K10: Equipments | L10: IT Equipments | M10: Land | N10: Total | T10: Buildings | U10: Vehicles | V10: Equipments | W10: IT Equipments | X10: Land | Y10: Total
A11: Balance at April 1, 2024 | B11: 739.33623 | C11: 1640.8464 | D11: 1145.9376 | E11: 3608.8915 | F11: 6159.4388 | G11: =SUM(B11:F11) -> 13294.451 | I11: 739.33623 | J11: 1640.8464 | K11: 1145.9376 | L11: 3608.8915 | M11: 6159.4388 | N11: =SUM(I11:M11) -> 13294.451 | O11: << Verified from PY Financial Statements >> | T11: =B11-I11 -> 0 | U11: =C11-J11 -> 0 | V11: =D11-K11 -> 0 | W11: =E11-L11 -> 0 | X11: =F11-M11 -> 0 | Y11: =G11-N11 -> 0
A12: Additions/ modifications during the year | B12: 22 | C12: 863 | D12: 27 | E12: 5924 | F12: 0 | G12: =SUM(B12:F12) -> 6836 | I12: 22 | J12: 863 | K12: 27 | L12: 5924 | M12: 0 | N12: =SUM(I12:M12) -> 6836 | O12: << Verified from PY Financial Statements >> | T12: =B12-I12 -> 0 | U12: =C12-J12 -> 0 | V12: =D12-K12 -> 0 | W12: =E12-L12 -> 0 | X12: =F12-M12 -> 0 | Y12: =G12-N12 -> 0
A13: Depreciation expense | B13: -448 | C13: -766 | D13: -352 | E13: -2943 | F13: -74 | G13: =SUM(B13:F13) -> -4583 | I13: -448 | J13: -766 | K13: -352 | L13: -2943 | M13: -74 | N13: =SUM(I13:M13) -> -4583 | O13: << Verified from PY Financial Statements >> | T13: =B13-I13 -> 0 | U13: =C13-J13 -> 0 | V13: =D13-K13 -> 0 | W13: =E13-L13 -> 0 | X13: =F13-M13 -> 0 | Y13: =G13-N13 -> 0
A14: Disposal/Adjustment during the year | B14: 2 | C14: -149 | D14: 0 | E14: 8 | F14: 0 | G14: =SUM(B14:F14) -> -139 | I14: 2 | J14: -149 | K14: 0 | L14: 8 | M14: 0 | N14: =SUM(I14:M14) -> -139 | O14: << Verified from PY Financial Statements >> | T14: =B14-I14 -> 0 | U14: =C14-J14 -> 0 | V14: =D14-K14 -> 0 | W14: =E14-L14 -> 0 | X14: =F14-M14 -> 0 | Y14: =G14-N14 -> 0
A15: Transferred of Assets under demerger | B15: -113 | C15: -648 | D15: 0 | E15: -163 | F15: 0 | G15: =SUM(B15:F15) -> -924 | I15: -113 | J15: -648 | K15: 0 | L15: -163 | M15: 0 | N15: =SUM(I15:M15) -> -924 | O15: << Verified from PY Financial Statements >> | T15: =B15-I15 -> 0 | U15: =C15-J15 -> 0 | V15: =D15-K15 -> 0 | W15: =E15-L15 -> 0 | X15: =F15-M15 -> 0 | Y15: =G15-N15 -> 0
A16: Transferred to Assets held for sale | B16: 0 | C16: -26 | D16: 0 | E16: 0 | F16: 0 | G16: =SUM(B16:F16) -> -26 | I16: 0 | J16: -26 | K16: 0 | L16: 0 | M16: 0 | N16: =SUM(I16:M16) -> -26 | O16: << Verified from PY Financial Statements >> | T16: =B16-I16 -> 0 | U16: =C16-J16 -> 0 | V16: =D16-K16 -> 0 | W16: =E16-L16 -> 0 | X16: =F16-M16 -> 0 | Y16: =G16-N16 -> 0
A17: Balance as at 31 March 2025 | B17: =SUM(B11:B16) -> 202.33623 | C17: =SUM(C11:C16) -> 914.8464 | D17: =SUM(D11:D16) -> 820.93765 | E17: =SUM(E11:E16) -> 6434.8915 | F17: =SUM(F11:F16) -> 6085.4388 | G17: =SUM(G11:G16) -> 14458.451 | I17: =SUM(I11:I16) -> 202.33623 | J17: =SUM(J11:J16) -> 914.8464 | K17: =SUM(K11:K16) -> 820.93765 | L17: =SUM(L11:L16) -> 6434.8915 | M17: =SUM(M11:M16) -> 6085.4388 | N17: =SUM(N11:N16) -> 14458.451 | O17: << Verified from PY Financial Statements >> | T17: =SUM(T11:T16) -> 0 | U17: =SUM(U11:U16) -> 0 | V17: =SUM(V11:V16) -> 0 | W17: =SUM(W11:W16) -> 0 | X17: =SUM(X11:X16) -> 0 | Y17: =SUM(Y11:Y16) -> 0
A19: Balance at April 1, 2025 | B19: =B17 -> 202.33623 | C19: =C17 -> 914.8464 | D19: =D17 -> 820.93765 | E19: =E17 -> 6434.8915 | F19: =F17 -> 6085.4388 | G19: =SUM(B19:F19) -> 14458.451 | I19: =I17 -> 202.33623 | J19: =J17 -> 914.8464 | K19: =K17 -> 820.93765 | L19: =L17 -> 6434.8915 | M19: =M17 -> 6085.4388 | N19: =N17 -> 14458.451 | O19: << Refer Link >> | T19: =B19-I19 -> 0 | U19: =C19-J19 -> 0 | V19: =D19-K19 -> 0 | W19: =E19-L19 -> 0 | X19: =F19-M19 -> 0 | Y19: =Y17 -> 0
A20: Additions/ modifications during the year | B20: 1867 | C20: 1225 | D20: 0 | E20: 5755 | F20: 0 | G20: =SUM(B20:F20) -> 8847 | I20: =Summary!C14 -> 0 | J20: =Summary!C15 -> 3248 | K20: =Summary!C16 -> 45 | L20: =Summary!C17 -> 61 | M20: 0 | N20: =SUM(I20:M20) -> 3354 | O20: << Refer Link >> | T20: =B20-I20 -> 1867 | U20: =C20-J20 -> -2023 | V20: =D20-K20 -> -45 | W20: =E20-L20 -> 5694 | X20: =F20-M20 -> 0 | Y20: =SUM(T20:X20) -> 5493
A21: Depreciation expense | B21: -340 | C21: -623 | D21: -400 | E21: -4330 | F21: -74 | G21: =SUM(B21:F21) -> -5767 | I21: =-Summary!E14 -> -394 | J21: =-Summary!E15 -> -911 | K21: =-Summary!E16 -> -357 | L21: =-Summary!$E$17 -> -4280 | M21: =M13 -> -74 | N21: =SUM(I21:M21) -> -6016 | O21: << Refer Link >> | T21: =B21-I21 -> 54 | U21: =C21-J21 -> 288 | V21: =D21-K21 -> -43 | W21: =E21-L21 -> -50 | X21: =F21-M21 -> 0 | Y21: =SUM(T21:X21) -> 249
A22: Disposal/Adjustment during the year | B22: -202 | C22: -137 | D22: -21 | E22: 0 | F22: 0 | G22: =SUM(B22:F22) -> -360 | I22: =-Summary!D14 -> 0 | J22: =-Summary!D15 -> 25 | K22: =-Summary!D16 -> 0 | L22: 0 | M22: 0 | N22: =SUM(I22:M22) -> 25 | O22: << Refer Link >> | T22: =B22-I22 -> -202 | U22: =C22-J22 -> -162 | V22: =D22-K22 -> -21 | W22: =E22-L22 -> 0 | X22: =F22-M22 -> 0 | Y22: =SUM(T22:X22) -> -385
A23: Balance as at 31 March 2026 | B23: =SUM(B19:B22) -> 1527.3362 | C23: =SUM(C19:C22) -> 1379.8464 | D23: =SUM(D19:D22) -> 399.93765 | E23: =SUM(E19:E22) -> 7859.8915 | F23: =SUM(F19:F22) -> 6011.4388 | G23: =SUM(G19:G22) -> 17178.451 | I23: =SUM(I19:I22) -> -191.66377 | J23: =SUM(J19:J22) -> 3276.8464 | K23: =Summary!F16 -> 88 | L23: =Summary!F17 -> 3573 | M23: =SUM(M19:M22) -> 6011.4388 | N23: =SUM(N19:N22) -> 11821.451 | O23: << Refer Link >> | T23: =B23-I23 -> 1719 | U23: =C23-J23 -> -1897 | V23: =D23-K23 -> 311.93765 | W23: =E23-L23 -> 4286.8915 | X23: =F23-M23 -> 0 | Y23: =G23-N23 -> 5357
N24: 0
A26: Note 4.5. Lease liabilities
T27: << Difference >>
A28: Particulars | B28: Buildings | C28: Vehicles | D28: Equipments | E28: IT Equipments | F28: Land | G28: Total | I28: Buildings | J28: Vehicles | K28: Equipments | L28: IT Equipments | M28: Land | N28: Total | T28: Buildings | U28: Vehicles | V28: Equipments | W28: IT Equipments | X28: Land | Y28: Total
A29: Balance as at 1 April 2024 | B29: 793.35015 | C29: 1604.4515 | D29: 1132 | E29: 3370.5952 | F29: 0 | G29: =SUM(B29:F29) -> 6900.3969 | I29: 793.35015 | J29: 1604.4515 | K29: 1132 | L29: 3370.5952 | M29: 0 | N29: =SUM(I29:M29) -> 6900.3969 | O29: << Verified from PY Financial Statements >> | T29: =B29-I29 -> 0 | U29: =C29-J29 -> 0 | V29: =D29-K29 -> 0 | W29: =E29-L29 -> 0 | X29: =F29-M29 -> 0 | Y29: =SUM(T29:X29) -> 0
A30: Additions/ modifications during the year | B30: 22 | C30: 854 | D30: 27 | E30: 5932 | F30: 0 | G30: =SUM(B30:F30) -> 6835 | I30: 22 | J30: 854 | K30: 27 | L30: 5932 | M30: 0 | N30: =SUM(I30:M30) -> 6835 | O30: << Verified from PY Financial Statements >> | T30: =B30-I30 -> 0 | U30: =C30-J30 -> 0 | V30: =D30-K30 -> 0 | W30: =E30-L30 -> 0 | X30: =F30-M30 -> 0 | Y30: =G30-N30 -> 0
A31: Accrual of finance cost | B31: 22 | C31: 101 | D31: 24 | E31: 493 | F31: 0 | G31: =SUM(B31:F31) -> 640 | I31: 22 | J31: 101 | K31: 24 | L31: 493 | M31: 0 | N31: =SUM(I31:M31) -> 640 | O31: << Verified from PY Financial Statements >> | T31: =B31-I31 -> 0 | U31: =C31-J31 -> 0 | V31: =D31-K31 -> 0 | W31: =E31-L31 -> 0 | X31: =F31-M31 -> 0 | Y31: =G31-N31 -> 0
A32: Payments | B32: -509 | C32: -818 | D32: -462 | E32: -3321 | F32: 0 | G32: =SUM(B32:F32) -> -5110 | I32: -509 | J32: -818 | K32: -462 | L32: -3321 | M32: 0 | N32: =SUM(I32:M32) -> -5110 | O32: << Verified from PY Financial Statements >> | T32: =B32-I32 -> 0 | U32: =C32-J32 -> 0 | V32: =D32-K32 -> 0 | W32: =E32-L32 -> 0 | X32: =F32-M32 -> 0 | Y32: =G32-N32 -> 0
A33: Adjustment on account of demerger | B33: 0 | C33: -154 | D33: 0 | E33: 0 | F33: 0 | G33: =SUM(B33:F33) -> -154 | I33: 0 | J33: -154 | K33: 0 | L33: 0 | M33: 0 | N33: =SUM(I33:M33) -> -154 | O33: << Verified from PY Financial Statements >> | T33: =B33-I33 -> 0 | U33: =C33-J33 -> 0 | V33: =D33-K33 -> 0 | W33: =E33-L33 -> 0 | X33: =F33-M33 -> 0 | Y33: =G33-N33 -> 0
A34: Adjustment for termination of leases | B34: -135 | C34: -663 | D34: 0 | E34: -151 | F34: 0 | G34: =SUM(B34:F34) -> -949 | I34: -135 | J34: -663 | K34: 0 | L34: -151 | M34: 0 | N34: =SUM(I34:M34) -> -949 | O34: << Verified from PY Financial Statements >> | T34: =B34-I34 -> 0 | U34: =C34-J34 -> 0 | V34: =D34-K34 -> 0 | W34: =E34-L34 -> 0 | X34: =F34-M34 -> 0 | Y34: =G34-N34 -> 0
A35: Transferred to Assets held for sale | B35: 0 | C35: -27 | D35: 0 | E35: 0 | F35: 0 | G35: =SUM(B35:F35) -> -27 | I35: 0 | J35: -27 | K35: 0 | L35: 0 | M35: 0 | N35: =SUM(I35:M35) -> -27 | O35: << Verified from PY Financial Statements >> | T35: =B35-I35 -> 0 | U35: =C35-J35 -> 0 | V35: =D35-K35 -> 0 | W35: =E35-L35 -> 0 | X35: =F35-M35 -> 0 | Y35: =G35-N35 -> 0
A36: Balance as at 31 March 2025 | B36: =SUM(B29:B35) -> 193.35015 | C36: =SUM(C29:C35) -> 897.45153 | D36: =SUM(D29:D35) -> 721 | E36: =SUM(E29:E35) -> 6323.5952 | F36: =SUM(F29:F35) -> 0 | G36: =SUM(G29:G35) -> 8135.3969 | I36: =SUM(I29:I35) -> 193.35015 | J36: =SUM(J29:J35) -> 897.45153 | K36: =SUM(K29:K35) -> 721 | L36: =SUM(L29:L35) -> 6323.5952 | M36: =SUM(M29:M35) -> 0 | N36: =SUM(N29:N35) -> 8135.3969 | O36: << Verified from PY Financial Statements >> | T36: =SUM(T29:T35) -> 0 | U36: =SUM(U29:U35) -> 0 | V36: =SUM(V29:V35) -> 0 | W36: =SUM(W29:W35) -> 0 | X36: =SUM(X29:X35) -> 0 | Y36: =SUM(Y29:Y35) -> 0
A37: Current | B37: 177 | C37: 406 | D37: 433 | E37: 3099 | F37: 0 | G37: =SUM(B37:F37) -> 4115 | I37: 177 | J37: 406 | K37: 433 | L37: 3099 | M37: 0 | N37: =SUM(I37:M37) -> 4115 | O37: << Verified from PY Financial Statements >> | T37: =B37-I37 -> 0 | U37: =C37-J37 -> 0 | V37: =D37-K37 -> 0 | W37: =E37-L37 -> 0 | X37: =F37-M37 -> 0 | Y37: =SUM(T37:X37) -> 0
A38: Non-current | B38: 16 | C38: 491 | D38: 288 | E38: 3225 | F38: 0 | G38: =SUM(B38:F38) -> 4020 | I38: 16 | J38: 491 | K38: 288 | L38: 3225 | M38: 0 | N38: =SUM(I38:M38) -> 4020 | O38: << Verified from PY Financial Statements >> | T38: =B38-I38 -> 0 | U38: =C38-J38 -> 0 | V38: =D38-K38 -> 0 | W38: =E38-L38 -> 0 | X38: =F38-M38 -> 0 | Y38: =SUM(T38:X38) -> 0
A40: Balance as at 1 April 2025 | B40: =B36 -> 193.35015 | C40: =C36 -> 897.45153 | D40: =D36 -> 721 | E40: =E36 -> 6323.5952 | F40: 0 | G40: =SUM(B40:F40) -> 8135.3969 | I40: =I36 -> 193.35015 | J40: =J36 -> 897.45153 | K40: =K36 -> 721 | L40: =L36 -> 6323.5952 | M40: 0 | N40: =SUM(I40:M40) -> 8135.3969 | O40: << Refer Link >> | T40: =B40-I40 -> 0 | U40: =C40-J40 -> 0 | V40: =D40-K40 -> 0 | W40: =E40-L40 -> 0 | X40: =F40-M40 -> 0 | Y40: =G40-N40 -> 0
A41: Additions/ modifications during the year | B41: =B20 -> 1867 | C41: =C20 -> 1225 | D41: 0 | E41: =E20 -> 5755 | F41: 0 | G41: =SUM(B41:F41) -> 8847 | I41: =Summary!H14 -> 0 | J41: =J20 -> 3248 | K41: =K20 -> 45 | L41: =Summary!H17 -> 61 | M41: =M20 -> 0 | N41: =SUM(I41:M41) -> 3354 | O41: << Refer Link >> | T41: =B41-I41 -> 1867 | U41: =C41-J41 -> -2023 | V41: =D41-K41 -> -45 | W41: =E41-L41 -> 5694 | X41: =F41-M41 -> 0 | Y41: =G41-N41 -> 5493
A42: Accrual of finance cost | B42: 123 | C42: 112 | D42: 32 | E42: 586 | F42: 0 | G42: =SUM(B42:F42) -> 853 | I42: =Summary!I14 -> 109 | J42: =Summary!I15 -> 202 | K42: =Summary!I16 -> 28 | L42: =Summary!I17 -> 406 | M42: 0 | N42: =SUM(I42:M42) -> 745 | O42: << Refer Link >> | T42: =B42-I42 -> 14 | U42: =C42-J42 -> -90 | V42: =D42-K42 -> 4 | W42: =E42-L42 -> 180 | X42: =F42-M42 -> 0 | Y42: =G42-N42 -> 108
A43: Payments | B43: -331 | C43: -693 | D43: -455 | E43: -4704 | F43: 0 | G43: =SUM(B43:F43) -> -6183 | I43: =-Summary!J14 -> -458 | J43: =-Summary!J15 -> -1040 | K43: =-Summary!J16 -> -331 | L43: =-Summary!J17 -> -4703 | M43: 0 | N43: =SUM(I43:M43) -> -6532 | O43: << Refer Link >> | T43: =B43-I43 -> 127 | U43: =C43-J43 -> 347 | V43: =D43-K43 -> -124 | W43: =E43-L43 -> -1 | X43: =F43-M43 -> 0 | Y43: =G43-N43 -> 349
A44: Adjustment for termination of leases | B44: -199 | C44: -134 | D44: -21 | E44: =-2 -> -2 | F44: 0 | G44: =SUM(B44:F44) -> -356 | I44: =-Summary!K14 -> 0 | J44: =-Summary!K15 -> 24 | K44: =-Summary!K16 -> 0 | L44: =-Summary!K17 -> 0 | M44: =-Summary!K18 -> 0 | N44: =SUM(I44:M44) -> 24 | O44: << Refer Link >> | T44: =B44-I44 -> -199 | U44: =C44-J44 -> -158 | V44: =D44-K44 -> -21 | W44: =E44-L44 -> -2 | X44: =F44-M44 -> 0 | Y44: =G44-N44 -> -380
A45: Balance as at 31 March 2026 | B45: =SUM(B40:B44) -> 1653.3502 | C45: =SUM(C40:C44) -> 1407.4515 | D45: =SUM(D40:D44) -> 277 | E45: =SUM(E40:E44) -> 7958.5952 | F45: =SUM(F40:F44) -> 0 | G45: =SUM(G40:G44) -> 11296.397 | I45: =SUM(I40:I44) -> -155.64985 | J45: =SUM(J40:J44) -> 3331.4515 | K45: =SUM(K40:K44) -> 463 | L45: =SUM(L40:L44) -> 2087.5952 | M45: =SUM(M40:M44) -> 0 | N45: =SUM(N40:N44) -> 5726.3969 | T45: =B45-I45 -> 1809 | U45: =C45-J45 -> -1924 | V45: =D45-K45 -> -186 | W45: =E45-L45 -> 5871 | X45: =F45-M45 -> 0 | Y45: =G45-N45 -> 5570
...

Sheet Summary
A1: =Scope!#REF! -> #REF!
A2: =Scope!#REF! -> #REF!
A3: =Scope!#REF! -> #REF!
A6: =Scope!A2 -> Purpose
A7: To document the summary of ROU Assets and Lease Liability
A10: Summary
B12: Right of Use Assets | G12: Lease Liability
A13: Particulars | B13: Net Block as at April 1, 2025 | C13: Addition | D13: Disposals | E13: Amortisation during FY 2025-26 | F13: Net Block as at March 31, 2026 | G13: Opening Balance | H13: Addition | I13: Interest | J13: Repayment | K13: Deletions/ Adjustment | L13: Closing Balance | M13: Sum of ST | N13: Sum of LT
A14: Building Lease | B14: =ROUND(SUMIF('Details 25-26'!$D:$D,$A14,'Details 25-26'!I:I)/10^5,0) -> 1527 | C14: =ROUND(SUMIF('Details 25-26'!$D:$D,$A14,'Details 25-26'!J:J)/10^5,0) -> 0 | D14: =ROUND(SUMIF('Details 25-26'!$D:$D,$A14,'Details 25-26'!K:K)/10^5,0) -> 0 | E14: =ROUND(SUMIF('Details 25-26'!$D:$D,$A14,'Details 25-26'!L:L)/10^5,0) -> 394 | F14: =B14+C14-D14-E14 -> 1133 | G14: =ROUND(SUMIF('Details 25-26'!$D:$D,$A14,'Details 25-26'!N:N)/10^5,0) -> 1653 | H14: =ROUND(SUMIF('Details 25-26'!$D:$D,$A14,'Details 25-26'!O:O)/10^5,0) -> 0 | I14: =ROUND(SUMIF('Details 25-26'!$D:$D,$A14,'Details 25-26'!P:P)/10^5,0) -> 109 | J14: =ROUND(SUMIF('Details 25-26'!$D:$D,$A14,'Details 25-26'!Q:Q)/10^5,0) -> 458 | K14: =ROUND(SUMIF('Details 25-26'!$D:$D,$A14,'Details 25-26'!R:R)/10^5,0) -> 0 | L14: =G14+H14+I14-J14-K14 -> 1304 | M14: =ROUND(SUMIF('Details 25-26'!$D:$D,$A14,'Details 25-26'!T:T)/10^5,0) -> 442 | N14: =ROUND(SUMIF('Details 25-26'!$D:$D,$A14,'Details 25-26'!U:U)/10^5,0) -> 863
A15: Vehicle Lease | B15: =ROUND(SUMIF('Details 25-26'!$D:$D,$A15,'Details 25-26'!I:I)/10^5,0) -> 1436 | C15: =ROUND(SUMIF('Details 25-26'!$D:$D,$A15,'Details 25-26'!J:J)/10^5,0) -> 3248 | D15: =ROUND(SUMIF('Details 25-26'!$D:$D,$A15,'Details 25-26'!K:K)/10^5,0) -> -25 | E15: =ROUND(SUMIF('Details 25-26'!$D:$D,$A15,'Details 25-26'!L:L)/10^5,0) -> 911 | F15: =B15+C15-D15-E15 -> 3798 | G15: =ROUND(SUMIF('Details 25-26'!$D:$D,$A15,'Details 25-26'!N:N)/10^5,0) -> 1474 | H15: =ROUND(SUMIF('Details 25-26'!$D:$D,$A15,'Details 25-26'!O:O)/10^5,0) -> 3248 | I15: =ROUND(SUMIF('Details 25-26'!$D:$D,$A15,'Details 25-26'!P:P)/10^5,0) -> 202 | J15: =ROUND(SUMIF('Details 25-26'!$D:$D,$A15,'Details 25-26'!Q:Q)/10^5,0) -> 1040 | K15: =ROUND(SUMIF('Details 25-26'!$D:$D,$A15,'Details 25-26'!R:R)/10^5,0) -> -24 | L15: =G15+H15+I15-J15-K15 -> 3908 | M15: =ROUND(SUMIF('Details 25-26'!$D:$D,$A15,'Details 25-26'!T:T)/10^5,0) -> 961 | N15: =ROUND(SUMIF('Details 25-26'!$D:$D,$A15,'Details 25-26'!U:U)/10^5,0) -> 2946
A16: Equipment Lease | B16: =ROUND(SUMIF('Details 25-26'!$D:$D,$A16,'Details 25-26'!I:I)/10^5,0) -> 400 | C16: =ROUND(SUMIF('Details 25-26'!$D:$D,$A16,'Details 25-26'!J:J)/10^5,0) -> 45 | D16: =ROUND(SUMIF('Details 25-26'!$D:$D,$A16,'Details 25-26'!K:K)/10^5,0) -> 0 | E16: =ROUND(SUMIF('Details 25-26'!$D:$D,$A16,'Details 25-26'!L:L)/10^5,0) -> 357 | F16: =B16+C16-D16-E16 -> 88 | G16: =ROUND(SUMIF('Details 25-26'!$D:$D,$A16,'Details 25-26'!N:N)/10^5,0) -> 277 | H16: =ROUND(SUMIF('Details 25-26'!$D:$D,$A16,'Details 25-26'!O:O)/10^5,0) -> 45 | I16: =ROUND(SUMIF('Details 25-26'!$D:$D,$A16,'Details 25-26'!P:P)/10^5,0) -> 28 | J16: =ROUND(SUMIF('Details 25-26'!$D:$D,$A16,'Details 25-26'!Q:Q)/10^5,0) -> 331 | K16: =ROUND(SUMIF('Details 25-26'!$D:$D,$A16,'Details 25-26'!R:R)/10^5,0) -> 0 | L16: =G16+H16+I16-J16-K16 -> 19 | M16: =ROUND(SUMIF('Details 25-26'!$D:$D,$A16,'Details 25-26'!T:T)/10^5,0) -> 20 | N16: =ROUND(SUMIF('Details 25-26'!$D:$D,$A16,'Details 25-26'!U:U)/10^5,0) -> 0
A17: IT Equipment Lease | B17: =ROUND(SUMIF('Details 25-26'!$D:$D,$A17,'Details 25-26'!I:I)/10^5,0) -> 7792 | C17: =ROUND(SUMIF('Details 25-26'!$D:$D,$A17,'Details 25-26'!J:J)/10^5,0) -> 61 | D17: =ROUND(SUMIF('Details 25-26'!$D:$D,$A17,'Details 25-26'!K:K)/10^5,0) -> 0 | E17: =ROUND(SUMIF('Details 25-26'!$D:$D,$A17,'Details 25-26'!L:L)/10^5,0) -> 4280 | F17: =B17+C17-D17-E17 -> 3573 | G17: =ROUND(SUMIF('Details 25-26'!$D:$D,$A17,'Details 25-26'!N:N)/10^5,0) -> 7893 | H17: =ROUND(SUMIF('Details 25-26'!$D:$D,$A17,'Details 25-26'!O:O)/10^5,0) -> 61 | I17: =ROUND(SUMIF('Details 25-26'!$D:$D,$A17,'Details 25-26'!P:P)/10^5,0) -> 406 | J17: =ROUND(SUMIF('Details 25-26'!$D:$D,$A17,'Details 25-26'!Q:Q)/10^5,0) -> 4703 | K17: =ROUND(SUMIF('Details 25-26'!$D:$D,$A17,'Details 25-26'!R:R)/10^5,0) -> 0 | L17: =G17+H17+I17-J17-K17 -> 3657 | M17: =ROUND(SUMIF('Details 25-26'!$D:$D,$A17,'Details 25-26'!T:T)/10^5,0) -> 2245 | N17: =ROUND(SUMIF('Details 25-26'!$D:$D,$A17,'Details 25-26'!U:U)/10^5,0) -> 1411
A18: Land | B18: 6085.4388 | C18: =ROUND(SUMIF('Details 25-26'!$D:$D,$A18,'Details 25-26'!J:J)/10^5,0) -> 0 | D18: =ROUND(SUMIF('Details 25-26'!$D:$D,$A18,'Details 25-26'!K:K)/10^5,0) -> 0 | E18: 74 | F18: =B18+C18-D18-E18 -> 6011.4388 | G18: 0 | H18: 0 | I18: 0 | J18: 0 | K18: 0 | L18: =G18+H18+I18-J18-K18 -> 0 | M18: =ROUND(SUMIF('Details 25-26'!$D:$D,$A18,'Details 25-26'!T:T)/10^5,0) -> 0 | N18: =ROUND(SUMIF('Details 25-26'!$D:$D,$A18,'Details 25-26'!U:U)/10^5,0) -> 0
A19: Grand Total | B19: =SUM(B14:B17) -> 11155 | C19: =SUM(C14:C17) -> 3354 | D19: =SUM(D14:D17) -> -25 | E19: =SUM(E14:E17) -> 5942 | F19: =SUM(F14:F17) -> 8592 | G19: =SUM(G14:G17) -> 11297 | H19: =SUM(H14:H17) -> 3354 | I19: =SUM(I14:I17) -> 745 | ... N19: =SUM(N14:N17) -> 5220

Sheet Testing
A1: =Scope!#REF! -> #REF!
A2: =Scope!#REF! -> #REF!
A3: =Scope!#REF! -> #REF!
A6: =Scope!A2 -> Purpose
A7: To document the summary of samples recomputed by ET.
A10: Lease ID | B10: Division | C10: Lease Type | D10: Lessor details | E10: Amount | F10: Testing Reference
A11: 64797 | B11: ITC | C11: IT Equipment Lease | D11: Hewlett-Packard Financial Services (India) Private Limited | E11: =_xlfn.XLOOKUP(A11,'Details 25-26'!B:B,'Details 25-26'!I:I) -> 18576235 | F11: ="<< Refer tab "&A11&" >>" -> << Refer tab 64797 >>
A12: 64806 | B12: ITC | C12: IT Equipment Lease | D12: Hewlett-Packard Financial Services (India) Private Limited | E12: =_xlfn.XLOOKUP(A12,'Details 25-26'!B:B,'Details 25-26'!I:I) -> 2.5323583e+08 | F12: ="<< Refer tab "&A12&" >>" -> << Refer tab 64806 >>
A13: 64807 | B13: ITC | C13: IT Equipment Lease | D13: Hewlett-Packard Financial Services (India) Private Limited | E13: =_xlfn.XLOOKUP(A13,'Details 25-26'!B:B,'Details 25-26'!I:I) -> 31042989 | F13: ="<< Refer tab "&A13&" >>" -> << Refer tab 64807 >>
A14: 64418 | B14: OCL | C14: Building Lease | D14: Workprovince Technology Private Limited | E14: =_xlfn.XLOOKUP(A14,'Details 25-26'!B:B,'Details 25-26'!I:I) -> 41405813 | F14: ="<< Refer tab "&A14&" -1"&" >>" -> << Refer tab 64418 -1 >>
A15: 64418 | B15: OCL | C15: Building Lease | D15: Workprovince Technology Private Limited | E15: =_xlfn.XLOOKUP(A15,'Details 25-26'!B:B,'Details 25-26'!I:I) -> 41405813 | F15: ="<< Refer tab "&A15&" -2"&" >>" -> << Refer tab 64418 -2 >>
A16: 59308 | B16: MMF | C16: IT Equipment Lease | D16: Cisco Systems Capital India Private Limited | E16: =_xlfn.XLOOKUP(A16,'Details 25-26'!B:B,'Details 25-26'!I:I) -> 16941688 | F16: ="<< Refer tab "&A16&" >>" -> << Refer tab 59308 >>
A17: 66353 | B17: MMF | C17: Vehicle Lease | D17: Shree Gajanan Corporation India Private Limited | E17: ='Details 25-26'!J27 -> 1.4217495e+08 | F17: ="<< Refer tab "&A17&" >>" -> << Refer tab 66353 >>
A18: 66354 | B18: MMF | C18: Vehicle Lease | D18: Shree Gajanan Corporation India Private Limited | E18: ='Details 25-26'!J28 -> 18970811 | F18: ="<< Refer tab "&A18&" >>" -> << Refer tab 66354 >>
A19: 53818 | B19: ITC | C19: IT Equipment Lease | D19: STT Telemedia Global Data Centre | E19: =_xlfn.XLOOKUP(A19,'Details 25-26'!B:B,'Details 25-26'!I:I) -> 42114950 | F19: ="<< Refer tab "&A19&" >>" -> << Refer tab 53818 >>
A20: 59268 | B20: ITC | C20: IT Equipment Lease | D20: Hewlett-Packard Financial Services (India) Private Limited | E20: =_xlfn.XLOOKUP(A20,'Details 25-26'!B:B,'Details 25-26'!I:I) -> 32928959 | F20: ="<< Refer tab "&A20&" >>" -> << Refer tab 59268 >>
A21: 60756 | B21: ITC | C21: IT Equipment Lease | D21: Hewlett-Packard Financial Services (India) Private Limited | E21: =_xlfn.XLOOKUP(A21,'Details 25-26'!B:B,'Details 25-26'!I:I) -> 26034322 | F21: ="<< Refer tab "&A21&" >>" -> << Refer tab 60756 >>
A22: 62007 | B22: ITC | C22: IT Equipment Lease | D22: Hewlett-Packard Financial Services (India) Private Limited | E22: =_xlfn.XLOOKUP(A22,'Details 25-26'!B:B,'Details 25-26'!I:I) -> 22626429 | F22: ="<< Refer tab "&A22&" >>" -> << Refer tab 62007 >>
A23: 64753 | B23: ITC | C23: IT Equipment Lease | D23: Cisco Systems Capital India Private Limited | E23: =_xlfn.XLOOKUP(A23,'Details 25-26'!B:B,'Details 25-26'!I:I) -> 19027935 | F23: ="<< Refer tab "&A23&" >>" -> << Refer tab 64753 >>
A24: 64754 | B24: ITC | C24: IT Equipment Lease | D24: Cisco Systems Capital India Private Limited | E24: =_xlfn.XLOOKUP(A24,'Details 25-26'!B:B,'Details 25-26'!I:I) -> 18680628 | F24: ="<< Refer tab "&A24&" >>" -> << Refer tab 64754 >>
A25: 64802 | B25: ITC | C25: IT Equipment Lease | D25: Hewlett-Packard Financial Services (India) Private Limited | E25: =_xlfn.XLOOKUP(A25,'Details 25-26'!B:B,'Details 25-26'!I:I) -> 28252051 | F25: ="<< Refer tab "&A25&" >>" -> << Refer tab 64802 >>
A26: 65449 | B26: ITC | C26: IT Equipment Lease | D26: Cisco Systems Capital India Private Limited | E26: =_xlfn.XLOOKUP(A26,'Details 25-26'!B:B,'Details 25-26'!I:I) -> 1.2309448e+08 | F26: ="<< Refer tab "&A26&" >>" -> << Refer tab 65449 >>
A27: 56754 | B27: ITC | C27: IT Equipment Lease | D27: Orix Leasing And Financial Services India Limited A37848 | E27: =_xlfn.XLOOKUP(A27,'Details 25-26'!B:B,'Details 25-26'!I:I) -> 987857.38 | F27: ="<< Refer tab "&A27&" >>" -> << Refer tab 56754 >>
A28: 57772 | B28: ITC | C28: IT Equipment Lease | D28: Hewlett-Packard Financial Services (India) Private Limited | E28: =_xlfn.XLOOKUP(A28,'Details 25-26'!B:B,'Details 25-26'!I:I) -> 5036147.2 | F28: ="<< Refer tab "&A28&" >>" -> << Refer tab 57772 >>
A29: 60014 | B29: ITC | C29: IT Equipment Lease | D29: Hewlett-Packard Financial Services (India) Private Limited | E29: =_xlfn.XLOOKUP(A29,'Details 25-26'!B:B,'Details 25-26'!I:I) -> 46481791 | F29: ="<< Refer tab "&A29&" >>" -> << Refer tab 60014 >>
A30: 62561 | B30: ITC | C30: IT Equipment Lease | D30: Hewlett-Packard Financial Services (India) Private Limited | E30: =_xlfn.XLOOKUP(A30,'Details 25-26'!B:B,'Details 25-26'!I:I) -> 83277964 | F30: ="<< Refer tab "&A30&" >>" -> << Refer tab 62561 >>
A31: 63100 | B31: ITC | C31: IT Equipment Lease | D31: Hewlett-Packard Financial Services (India) Private Limited | E31: =_xlfn.XLOOKUP(A31,'Details 25-26'!B:B,'Details 25-26'!I:I) -> 10884953 | F31: ="<< Refer tab "&A31&" >>" -> << Refer tab 63100 >>
A32: Rent Alpha Private Limited | B32: WIND | C32: Equipment Lease | D32: Rent Alpha Private Limited | E32: =_xlfn.XLOOKUP(A32,'Details 25-26'!B:B,'Details 25-26'!I:I) -> 40015641 | F32: ="<< Refer tab "&A32&" >>" -> << Refer tab Rent Alpha Private Limited >>

Sheet Vehicle Policy Analysis
A1: =Testing!A1 -> #REF!
A2: =Testing!A2 -> #REF!
A3: =Testing!A3 -> #REF!
A5: Work Done
A6: ET has obtained vehicle policy and performed an analysis of the same.
A8: Area | B8: Key Provision
A9: Objective | B9: Provides eligible employees with a company car lease for business and reasonable personal use.
A10: Coverage | B10: Applicable to permanent employees in LPB and SPB bands in India with a local employment contract.
A11: Eligibility Limits | B11: Vehicle value eligibility ranges from ₹14 lakh to ₹32 lakh depending on employee band and lease tenure.
A12: Lease | B12: Employees can opt for a 3, 4, or 5-year lease. Once selected, tenure cannot be changed.
A13: Fuel & Maintenance Benefit | B13: Annual reimbursement capped at ₹2 lakh (LPB- Lead Professional Band) and ₹2.5 lakh (SPB- Senior Professional Band) against supporting bills
A14: Cost Allocation | B14: Company bears insurance cost during lease tenure; employee bears lease rentals, road tax, registration charges, fines, and other applicable taxes.
A15: End of | B15: Employee is responsible for closing the lease, obtaining NDC, and purchasing the vehicle from the leasing company at lease expiry.
A16: Employee Obligations | B16: Employee must maintain the vehicle, comply with traffic laws, and bear uninsured losses, damages, and penalties.
A17: Key Restriction | B17: Vehicle usage should not exceed 15,000 km per year on average; excess usage charges may apply.

Sheet Details 25-26
A1: =Scope!#REF! -> #REF!
A2: =Scope!#REF! -> #REF!
A3: =Scope!#REF! -> #REF!
A5: Purpose
A6: To document the schedule for ROU Assets and Lease Liability.
H8: =SUBTOTAL(9,H11:H2529) -> 11676309 | I8: =SUBTOTAL(9,I11:I2529) -> 1.1156086e+09 | J8: =SUBTOTAL(9,J11:J2529) -> 3.353532e+08 | K8: =SUBTOTAL(9,K11:K2529) -> -2542050.4 | L8: =SUBTOTAL(9,L11:L2529) -> 5.9424369e+08 | M8: =SUBTOTAL(9,M11:M2529) -> 8.5926012e+08 | N8: =SUBTOTAL(9,N11:N2529) -> 1.1296833e+09 | O8: =SUBTOTAL(9,O11:O2529) -> 3.353532e+08 | ... U8: =SUBTOTAL(9,U11:U2529) -> 5.2197959e+08
I9: ROU | N9: Lease Liability
A10: S.No | B10: System Lease ID | C10: Division | D10: Lease Template | E10: Discount Rate | F10: Commencement Date | G10: Expiration Date | H10: Monthly Payments | I10: Opening Balance as on April'25 | J10: Addition during FY 2025-26 | K10: Deletions/ Adjustment during FY 2025-26 | L10: Amortisation during FY 2025-26 | M10: Closing Balance | N10: Opening Balance | O10: Addition during the year | P10: Interest | Q10: Repayment | R10: Deletion during the year | S10: Closing Balance | T10: ST | U10: LT
A11: 1 | B11: 60272 | C11: MMF | D11: Vehicle Lease | E11: 4.4375 | F11: 44986 | G11: 46124 | H11: 35593.85 | I11: 659457.49 | J11: 0 | K11: -37247.4 | L11: 400867.72 | M11: =I11+J11-K11-L11 -> 295837.17 | N11: 687503.51 | O11: 0 | P11: 36500.42 | Q11: 433959.16 | R11: -37247.4 | S11: =N11+O11+P11-Q11-R11 -> 327292.17 | T11: 327291.7 | U11: 0
A12: =A11+1 -> 2 | B12: 61193 | C12: MMF | D12: Vehicle Lease | E12: 4.698 | F12: 45047 | G12: 46498 | H12: 27611.88 | I12: 615109.1 | J12: 0 | K12: -11137.05 | L12: 296354.24 | M12: =I12+J12-K12-L12 -> 329891.91 | N12: 633798.3 | O12: 0 | P12: 38432.04 | Q12: 333162.8 | R12: -11137.05 | S12: =N12+O12+P12-Q12-R12 -> 350204.59 | T12: 322137.84 | U12: 28066.94
A13: =A12+1 -> 3 | B13: 61200 | C13: MMF | D13: Vehicle Lease | E13: 4.698 | F13: 45047 | G13: 46498 | H13: 17701.46 | I13: 394335.25 | J13: 0 | K13: -4031.03 | L13: 189242.56 | M13: =I13+J13-K13-L13 -> 209123.72 | N13: 406316.69 | O13: 0 | P13: 24564.61 | Q13: 212811.96 | R13: -4031.03 | S13: =N13+O13+P13-Q13-R13 -> 222100.37 | T13: 204300.02 | U13: 17800.07
A14: =A13+1 -> 4 | B14: 61205 | C14: MMF | D14: Vehicle Lease | E14: 4.698 | F14: 45047 | G14: 46507 | H14: 33574.42 | I14: 766842.83 | J14: 0 | K14: -25.97 | L14: 361349.76 | M14: =I14+J14-K14-L14 -> 405519.04 | N14: 801230.71 | O14: 0 | P14: 48785.27 | Q14: 409744.72 | R14: -25.97 | S14: =N14+O14+P14-Q14-R14 -> 440297.23 | T14: 405009.89 | U14: 35287.34
A15: =A14+1 -> 5 | B15: 61209 | C15: MMF | D15: Vehicle Lease | E15: 4.698 | F15: 45047 | G15: 46507 | H15: 25441.09 | I15: 581076.73 | J15: 0 | K15: 18603.13 | L15: 269431.72 | M15: =I15+J15-K15-L15 -> 293041.88 | N15: 607134.72 | O15: 0 | P15: 36527.14 | Q15: 305857.36 | R15: 18603.13 | S15: =N15+O15+P15-Q15-R15 -> 319201.37 | T15: 293618.84 | U15: 25582.16
A16: =A15+1 -> 6 | B16: 62974 | C16: MMF | D16: Vehicle Lease | E16: 4.8266 | F16: 45170 | G16: 46668 | H16: 21973.84 | I16: 564437.74 | J16: 0 | K16: -3900.01 | L16: 235793.36 | M16: =I16+J16-K16-L16 -> 332544.39 | N16: 583119.97 | O16: 0 | P16: 34499.16 | Q16: 264241.76 | R16: -3900.01 | S16: =N16+O16+P16-Q16-R16 -> 357277.38 | T16: 248119.12 | U16: 109157.99
A17: =A16+1 -> 7 | B17: 62980 | C17: MMF | D17: Vehicle Lease | E17: 4.8266 | F17: 45169 | G17: 46629 | H17: 24788.47 | I17: 642481.88 | J17: 0 | K17: -29982.71 | L17: 267290.72 | M17: =I17+J17-K17-L17 -> 405173.87 | N17: 657812.3 | O17: 0 | P17: 39499.4 | Q17: 303280.6 | R17: -29982.71 | S17: =N17+O17+P17-Q17-R17 -> 424013.81 | T17: 294465.38 | U17: 129547.65
A18: =A17+1 -> 8 | B18: 59308 | C18: MMF | D18: IT Equipment Lease | E18: 5.1215 | F18: 44926 | G18: 46691 | H18: 606609.11 | I18: 16941688 | J18: 0 | K18: 0 | L18: 6558072.7 | M18: =I18+J18-K18-L18 -> 10383615 | N18: 17653948 | O18: 0 | P18: 720542.53 | Q18: 7279309.3 | R18: 0 | S18: =N18+O18+P18-Q18-R18 -> 11095181 | T18: 6902672.2 | U18: 4192508.5
A19: =A18+1 -> 9 | B19: 64733 | C19: MMF | D19: Vehicle Lease | E19: 7.4689 | F19: 45422 | G19: 47247 | H19: 48438.24 | I19: 1999679.8 | J19: 0 | K19: 146835.18 | L19: 501057.8 | M19: =I19+J19-K19-L19 -> 1351786.8 | N19: 2052968 | O19: 0 | P19: 138138.14 | Q19: 593044.52 | R19: 0 | S19: =N19+O19+P19-Q19-R19 -> 1598061.6 | T19: 580776 | U19: 1017285.6
A20: =A19+1 -> 10 | B20: 64752 | C20: MMF | D20: Vehicle Lease | E20: 7.4689 | F20: 45422 | G20: 46516 | H20: 26324.8 | I20: 598499.66 | J20: 0 | K20: 480173.86 | L20: 118325.8 | M20: =I20+J20-K20-L20 -> 0 | N20: 611508.89 | O20: 0 | P20: 16790.59 | Q20: 131624 | R20: 496675.48 | S20: =N20+O20+P20-Q20-R20 -> 0 | T20: 0 | U20: 0
A21: =A20+1 -> 11 | B21: 65270 | C21: MMF | D21: Vehicle Lease | E21: 7.3028 | F21: 45536 | G21: 45897 | H21: 38401.24 | I21: 183631 | J21: 0 | K21: 0 | L21: 183631.27 | M21: =I21+J21-K21-L21 -> -0.27 | N21: 189697 | O21: 0 | P21: 2308.83 | Q21: 192006.2 | R21: 0 | S21: =N21+O21+P21-Q21-R21 -> -0.37 | T21: 0 | U21: 0
A22: =A21+1 -> 12 | B22: 65366 | C22: MMF | D22: Vehicle Lease | E22: 7.8173 | F22: 45549 | G22: 47374 | H22: 25782.09 | I22: 1144676.2 | J22: 0 | K22: -75042.02 | L22: 263677.04 | M22: =I22+J22-K22-L22 -> 956041.18 | N22: 1159883.2 | O22: 0 | P22: 82456.16 | Q22: 314979 | R22: -75042.02 | S22: =N22+O22+P22-Q22-R22 -> 1002402.4 | T22: 259083 | U22: 743319.44
A23: =A22+1 -> 13 | B23: 65884 | C23: MMF | D23: Vehicle Lease | E23: 7.3469 | F23: 45795 | G23: 47620 | H23: 37122.22 | I23: 0 | J23: 1870722.9 | K23: -57608.42 | L23: 330171.13 | M23: =I23+J23-K23-L23 -> 1598160.2 | N23: 0 | O23: 1870722.9 | P23: 115987.3 | Q23: 411009.7 | R23: -57608.42 | S23: =N23+O23+P23-Q23-R23 -> 1633308.9 | T23: 347797.83 | U23: 1285511.1
... A28: =A27+1 -> 18 | B28: 66354 | C28: MMF | D28: Vehicle Lease | E28: 7.6675 | F28: 45992 | G28: 48182 | H28: 285165 | I28: 0 | J28: 18970811 | K28: 0 | L28: 1053933.9 | M28: =I28+J28-K28-L28 -> 17916877 | N28: 0 | O28: 18970811 | P28: 471191.95 | Q28: 1140660 | R28: 0 | S28: =N28+O28+P28-Q28-R28 -> 18301343 | T28: 2113849.9 | U28: 16187493
A29: =A28+1 -> 19 | B29: 52815 | C29: OCL | D29: Vehicle Lease | E29: 1.3148 | F29: 44470 | G29: 45899 | H29: 28583.98 | I29: 123356.37 | J29: =0 -> 0 | K29: =0 -> 0 | L29: 123356.37 | M29: =I29+J29-K29-L29 -> 0 | N29: 113295.64 | O29: =0 -> 0 | P29: 29624.26 | Q29: 142919.9 | R29: =0 -> 0 | S29: =N29+O29+P29-Q29-R29 -> 0 | T29: 0 | U29: 0
A30: =A29+1 -> 20 | B30: 57761 | C30: OCL | D30: Vehicle Lease | E30: 7.3531 | F30: 44707 | G30: 46167 | H30: 23776.33 | I30: 282820.91 | J30: =0 -> 0 | K30: -23641.5 | L30: 262102.68 | M30: =I30+J30-K30-L30 -> 44359.73 | N30: 298045.98 | O30: =0 -> 0 | P30: 11625.07 | Q30: 285708.84 | R30: -23641.5 | S30: =N30+O30+P30-Q30-R30 -> 47603.71 | T30: 0 | U30: 47603.71
A31: =A30+1 -> 21 | B31: 57765 | C31: OCL | D31: Vehicle Lease | E31: 7.3531 | F31: 44774 | G31: 46187 | H31: 35265.05 | I31: 441634.41 | J31: =0 -> 0 | K31: -42182.7 | L31: 392014.96 | M31: =I31+J31-K31-L31 -> 91802.15 | N31: 474634.59 | O31: =0 -> 0 | P31: 19820.94 | Q31: 427559.16 | R31: -42182.7 | S31: =N31+O31+P31-Q31-R31 -> 109079.07 | T31: 0 | U31: 109079.07
A32: =A31+1 -> 22 | B32: 57774 | C32: OCL | D32: Vehicle Lease | E32: 7.3531 | F32: 44774 | G32: 46203 | H32: 19340.58 | I32: 256260.26 | J32: =0 -> 0 | K32: -19273.25 | L32: 211690.4 | M32: =I32+J32-K32-L32 -> 63843.11 | N32: 278060.64 | O32: =0 -> 0 | P32: 12165.61 | Q32: 232466.08 | R32: -19273.25 | S32: =N32+O32+P32-Q32-R32 -> 77033.42 | T32: 0 | U32: 77033.42
A33: =A32+1 -> 23 | B33: 58553 | C33: OCL | D33: Vehicle Lease | E33: 7.1163 | F33: 44805 | G33: 45900 | H33: 23422.29 | I33: 114477.31 | J33: =0 -> 0 | K33: =0 -> 0 | L33: 114477.31 | M33: =I33+J33-K33-L33 -> 0 | N33: 115738.75 | O33: =0 -> 0 | P33: 1372.7 | Q33: 117111.45 | R33: =0 -> 0 | S33: =N33+O33+P33-Q33-R33 -> 0 | T33: 0 | U33: 0
A34: =A33+1 -> 24 | B34: 64306 | C34: OCL | D34: Vehicle Lease | E34: 7.62 | F34: 45289 | G34: 46749 | H34: 114408.86 | I34: 4210036.7 | J34: =0 -> 0 | K34: -401941.95 | L34: 1547732.5 | M34: =I34+J34-K34-L34 -> 3064246.1 | N34: 4288565.9 | O34: =0 -> 0 | P34: 262955.68 | Q34: 1735287.8 | R34: -401941.95 | S34: =N34+O34+P34-Q34-R34 -> 3218175.7 | T34: 1797207.7 | U34: 1420968.1
A35: =A34+1 -> 25 | B35: 64418 | C35: OCL | D35: Building Lease | E35: 7.57 | F35: 45606 | G35: 47163 | H35: 960825 | I35: 41405813 | J35: =0 -> 0 | K35: =0 -> 0 | L35: 10685371 | M35: =I35+J35-K35-L35 -> 30720442 | N35: 41816461 | O35: =0 -> 0 | P35: 2793767.7 | Q35: 11610541 | R35: =0 -> 0 | S35: =N35+O35+P35-Q35-R35 -> 32999688 | T35: 11170343 | U35: 21829345
A36: =A35+1 -> 26 | B36: 64418 | C36: OCL | D36: Building Lease | E36: 7.485 | F36: 45336 | G36: 47162 | H36: 2700000 | I36: 1.1132711e+08 | J36: =0 -> 0 | K36: =0 -> 0 | L36: 28751660 | M36: =I36+J36-K36-L36 -> 82575451 | N36: 1.2350436e+08 | O36: =0 -> 0 | P36: 8154950.2 | Q36: 34237688 | R36: =0 -> 0 | S36: =N36+O36+P36-Q36-R36 -> 97421626 | T36: 32988176 | U36: 64433450
A37: =A36+1 -> 27 | B37: 64719 | C37: OCL | D37: Vehicle Lease | E37: 7.64 | F37: 45403 | G37: 46863 | H37: 26474.88 | I37: 839425.41 | J37: =0 -> 0 | K37: -67549.42 | L37: 284146.56 | M37: =I37+J37-K37-L37 -> 622828.27 | N37: 854720.1 | O37: =0 -> 0 | P37: 55831.75 | Q37: 324531.12 | R37: -67549.42 | S37: =N37+O37+P37-Q37-R37 -> 653570.15 | T37: 318475.82 | U37: 335094.33
A38: =A37+1 -> 28 | B38: 64729 | C38: OCL | D38: Vehicle Lease | E38: 7.81 | F38: 45431 | G38: 47256 | H38: 29270.46 | I38: 1205959.2 | J38: =0 -> 0 | K38: 1132989.6 | L38: 72969.57 | M38: =I38+J38-K38-L38 -> 0 | N38: 1232556.6 | O38: =0 -> 0 | P38: 23084.82 | Q38: 87811.38 | R38: 1167830.1 | S38: =N38+O38+P38-Q38-R38 -> 0 | T38: 0 | U38: 0
A39: =A38+1 -> 29 | B39: 64761 | C39: OCL | D39: Vehicle Lease | E39: 7.64 | F39: 45464 | G39: 46924 | H39: 40099.87 | I39: 1340776.5 | J39: =0 -> 0 | K39: 1340776.5 | L39: 0 | M39: =I39+J39-K39-L39 -> 0 | N39: 1358201.9 | O39: =0 -> 0 | P39: =0 -> 0 | Q39: =0 -> 0 | R39: 1358201.9 | S39: =N39+O39+P39-Q39-R39 -> 0 | T39: 0 | U39: 0
A40: =A39+1 -> 30 | B40: 65689 | C40: OCL | D40: Vehicle Lease | E40: 7.24 | F40: 45700 | G40: 46794 | H40: 45726.35 | I40: 1418224.7 | J40: =0 -> 0 | K40: -124717.34 | L40: 513938.64 | M40: =I40+J40-K40-L40 -> 1029003.4 | N40: 1410213.4 | O40: =0 -> 0 | P40: 86410.67 | Q40: 562416.56 | R40: -124717.34 | S40: =N40+O40+P40-Q40-R40 -> 1058924.9 | T40: 563913.45 | U40: 495011.45
A41: =A40+1 -> 31 | B41: 65816 | C41: OCL | D41: Vehicle Lease | E41: 7.14 | F41: 45778 | G41: 47165 | H41: 48893.45 | I41: 0 | J41: 1955486.9 | K41: =0 -> 0 | L41: 455639.82 | M41: =I41+J41-K41-L41 -> 1499847 | N41: 0 | O41: 1955486.9 | P41: 108320.04 | Q41: 513985.95 | R41: =0 -> 0 | S41: =N41+O41+P41-Q41-R41 -> 1549821 | T41: 522711.82 | U41: 1027109.1
A42: =A41+1 -> 32 | B42: 66078 | C42: OCL | D42: Vehicle Lease | E42: 7.02 | F42: 45898 | G42: 47358 | H42: 50494.14 | I42: 0 | J42: 2147091.2 | K42: =0 -> 0 | L42: 306113.35 | M42: =I42+J42-K42-L42 -> 1840977.8 | N42: 0 | O42: 2147091.2 | P42: 87740.27 | Q42: 388149.08 | R42: =0 -> 0 | S42: =N42+O42+P42-Q42-R42 -> 1846682.4 | T42: 522288.42 | U42: 1324393.9
A43: =A42+1 -> 33 | B43: 65910 | C43: OCL | D43: Vehicle Lease | E43: 7.35 | F43: 45800 | G43: 47625 | H43: 19680.52 | I43: 0 | J43: 999816.3 | K43: =0 -> 0 | L43: 164600.73 | M43: =I43+J43-K43-L43 -> 835215.57 | N43: 0 | O43: 999816.3 | P43: 58585.36 | Q43: 207763.65 | R43: =0 -> 0 | S43: =N43+O43+P43-Q43-R43 -> 850638.01 | T43: 191364.23 | U43: 659273.78
A44: =A43+1 -> 34 | B44: 65969 | C44: OCL | D44: Vehicle Lease | E44: 6.89 | F44: 45817 | G44: 46912 | H44: 47586.61 | I44: 0 | J44: 1574931.1 | K44: =0 -> 0 | L44: 406651.64 | M44: =I44+J44-K44-L44 -> 1168279.5 | N44: 0 | O44: 1574931.1 | P44: 73454.08 | Q44: 454472.86 | R44: =0 -> 0 | S44: =N44+O44+P44-Q44-R44 -> 1193912.3 | T44: 534775.05 | U44: 659137.28
A45: =A44+1 -> 35 | B45: 66253 | C45: OCL | D45: Vehicle Lease | E45: 6.78 | F45: 45998 | G45: 47093 | H45: 21397.47 | I45: 0 | J45: 699202.72 | K45: =0 -> 0 | L45: 73930.05 | M45: =I45+J45-K45-L45 -> 625272.67 | N45: 0 | O45: 699202.72 | P45: 14715.34 | Q45: 85589.88 | R45: =0 -> 0 | S45: =N45+O45+P45-Q45-R45 -> 628328.18 | T45: 234027.46 | U45: 394300.72
A46: =A45+1 -> 36 | B46: 65789 | C46: OCL | D46: Vehicle Lease | E46: 7.35 | F46: 45778 | G46: 47603 | H46: 35457.73 | I46: 0 | J46: 1775760.5 | K46: =0 -> 0 | L46: 314639.77 | M46: =I46+J46-K46-L46 -> 1461120.7 | N46: 0 | O46: 1775760.5 | P46: 104950.87 | Q46: 374437.28 | R46: =0 -> 0 | S46: =N46+O46+P46-Q46-R46 -> 1506274.1 | T46: 346885.33 | U46: 1159388.7
...

Sheet Rate impact
A1: =Scope!#REF! -> #REF!
A2: =Scope!#REF! -> #REF!
A3: =Scope!#REF! -> #REF!
A6: Purpose
A7: To compute the amount of unadjusted difference due to low discount rate considered by the company.
A10: Particulars | B10: As per schedule | C10: As per DHS | D10: Difference
A11: ROU | B11: =SUM(K19) -> 12654747 | C11: =AB20 -> 11320748 | D11: =B11-C11 -> 1333998.7 | E11: <<Imm>>
A12: Difference in Interest (Calculated on the basis of 7% rate on difference in ROU computed for average months completed i.e. 37 months) | D12: =(D11*0.07/12)*37 -> 287921.4 | E12: <<Imm>>
A13: Difference in Depreciation charged till date | D13: =J19-AA20 -> 1405932.5 | E13: <<Imm>>
A16: Obervation
A17: ET observed that the difference due to low rates is not material.
H19: =SUM(H21:H30) -> 21288785 | I19: =SUM(I21:I30) -> 8701759.2 | J19: =SUM(J21:J30) -> 28568120 | K19: =SUM(K21:K30) -> 12654747 | L19: =SUM(L22:L29) -> 2271132 | M19: =SUM(M22:M29) -> 0 | N19: =SUM(N22:N29) -> 718221.84 | O19: =SUM(O22:O29) -> 10932960 | P19: =SUM(P22:P29) -> 0 | Q19: =SUM(Q22:Q29) -> 0 | R19: =SUM(R22:R29) -> 4612238.7
H20: ROU | L20: Lease Liability | Z20: 46112 | AA20: =SUM(AA22:AA30) -> 27162188 | AB20: =SUM(AB22:AB30) -> 11320748 | AD20: =SUM(AD22:AD30) -> 1333998.7
A21: System Lease ID | B21: Division | C21: Lease Template | D21: Discount Rate | E21: Commencement Date | F21: Expiration Date | G21: Monthly Payments | H21: Opening Balance as on April'25 | I21: Amortisation during FY 2025-26 | J21: Amortisation till FY 2025-26 | K21: Closing Balance | L21: Opening Balance | M21: Addition during the year | N21: Interest | O21: Repayment | P21: Deletion during the year | Q21: Transfer due to Demerger | R21: Closing Balance | T21: Discount Rate | U21: Commencement Date | V21: Expiration Date | W21: Monthly Payments | X21: Period | Y21: ROU | Z21: Months till March 31, 2026 | AA21: Depreciation till March 31, 2026 | AB21: Closing balance as on March 31, 2026 | AD21: Difference in Closing balance of ROU
A22: 60272 | B22: MMF | C22: Vehicle Lease | D22: 4.4375 | E22: 44986 | F22: 46124 | G22: 35593.85 | H22: 659457.49 | I22: 400867.72 | J22: 1231917.8 | K22: 295837.17 | L22: 295837.17 | M22: 0 | N22: 42150.98 | O22: 343007.76 | P22: 0 | Q22: 0 | R22: 437035.74 | T22: 0.07 | U22: =E22 -> 44986 | V22: =F22 -> 46124 | W22: =G22 -> 35593.85 | X22: =(V22-U22)/30 -> 37.933333 | Y22: =-PV((T22/12),X22,W22) -> 1208099.3 | Z22: =($Z$20-U22)/30 -> 37.533333 | AA22: =Y22/X22*Z22 -> 1195360.1 | AB22: =Y22-AA22 -> 12739.184 | AD22: =K22-AB22 -> 283097.99
A23: 61193 | B23: MMF | C23: Vehicle Lease | D23: 4.698 | E23: 45047 | F23: 46498 | G23: 27611.88 | H23: 615109.1 | I23: 296354.24 | J23: 877429.61 | K23: 329891.91 | L23: 329891.91 | M23: 0 | N23: 44359.84 | O23: 319561.92 | P23: 0 | Q23: 0 | R23: 479173.68 | T23: 0.07 | U23: =E23 -> 45047 | V23: =F23 -> 46498 | W23: =G23 -> 27611.88 | X23: =ROUNDDOWN((V23-U23)/30,0) -> 48 | Y23: =-PV((T23/12),X23,W23) -> 1153077.7 | Z23: =($Z$20-U23)/30 -> 35.5 | AA23: =Y23/X23*Z23 -> 852797.03 | AB23: =Y23-AA23 -> 300280.64 | AD23: =K23-AB23 -> 29611.267
A24: 61200 | B24: MMF | C24: Vehicle Lease | D24: 4.698 | E24: 45047 | F24: 46498 | G24: 17701.46 | H24: 394335.25 | I24: 189242.56 | J24: 561758.99 | K24: 209123.72 | L24: 209123.72 | M24: 0 | N24: 330921.15 | O24: 6122556 | P24: 0 | Q24: 0 | R24: 1520641.7 | T24: 0.07 | U24: =E24 -> 45047 | V24: =F24 -> 46498 | W24: =G24 -> 17701.46 | X24: =ROUNDDOWN((V24-U24)/30,0) -> 48 | Y24: =-PV((T24/12),X24,W24) -> 739216.53 | Z24: =($Z$20-U24)/30 -> 35.5 | AA24: =Y24/X24*Z24 -> 546712.23 | AB24: =Y24-AA24 -> 192504.31 | AD24: =K24-AB24 -> 16619.414
A25: 61205 | B25: MMF | C25: Vehicle Lease | D25: 4.698 | E25: 45047 | F25: 46507 | G25: 33574.42 | H25: 766842.83 | I25: 361349.76 | J25: 1077069.9 | K25: 405519.04 | L25: 405519.04 | M25: 0 | N25: 105245.3 | O25: 1806060.6 | P25: 0 | Q25: 0 | R25: 596332.41 | T25: 0.07 | U25: =E25 -> 45047 | V25: =F25 -> 46507 | W25: =G25 -> 33574.42 | X25: =ROUNDDOWN((V25-U25)/30,0) -> 48 | Y25: =-PV((T25/12),X25,W25) -> 1402074.5 | Z25: =($Z$20-U25)/30 -> 35.5 | AA25: =Y25/X25*Z25 -> 1036951 | AB25: =Y25-AA25 -> 365123.58 | AD25: =K25-AB25 -> 40395.462
A26: 61209 | B26: MMF | C26: Vehicle Lease | D26: 4.698 | E26: 45047 | F26: 46507 | G26: 25441.09 | H26: 581076.73 | I26: 269431.72 | J26: 811770.25 | K26: 293041.88 | L26: 293041.88 | M26: 0 | N26: 78646.48 | O26: 1121136 | P26: 0 | Q26: 0 | R26: 551778.15 | T26: 0.07 | U26: =E26 -> 45047 | V26: =F26 -> 46507 | W26: =G26 -> 25441.09 | X26: =ROUNDDOWN((V26-U26)/30,0) -> 48 | Y26: =-PV((T26/12),X26,W26) -> 1062425 | Z26: =($Z$20-U26)/30 -> 35.5 | AA26: =Y26/X26*Z26 -> 785751.85 | AB26: =Y26-AA26 -> 276673.19 | AD26: =K26-AB26 -> 16368.692
A27: 62974 | B27: MMF | C27: Vehicle Lease | D27: 4.8266 | E27: 45170 | F27: 46668 | G27: 21973.84 | H27: 564437.74 | I27: 235793.36 | J27: 619092.34 | K27: 332544.39 | L27: 332544.39 | M27: 0 | N27: 38504.13 | O27: 506430.6 | P27: 0 | Q27: 0 | R27: 289870.84 | T27: 0.07 | U27: =E27 -> 45170 | V27: =F27 -> 46668 | W27: =G27 -> 21973.84 | X27: =ROUNDDOWN((V27-U27)/30,0) -> 49 | Y27: =-PV((T27/12),X27,W27) -> 934156.58 | Z27: =($Z$20-U27)/30 -> 31.4 | AA27: =Y27/X27*Z27 -> 598622.79 | AB27: =Y27-AA27 -> 335533.79 | AD27: =K27-AB27 -> -2989.401
A28: 62980 | B28: MMF | C28: Vehicle Lease | D28: 4.8266 | E28: 45169 | F28: 46629 | G28: 24788.47 | H28: 642481.88 | I28: 267290.72 | J28: 694610.17 | K28: 405173.87 | L28: 405173.87 | M28: 0 | N28: 37651.37 | O28: 379600.92 | P28: 0 | Q28: 0 | R28: 337168.91 | T28: 0.07 | U28: =E28 -> 45169 | V28: =F28 -> 46629 | W28: =G28 -> 24788.47 | X28: =ROUNDDOWN((V28-U28)/30,0) -> 48 | Y28: =-PV((T28/12),X28,W28) -> 1035171.5 | Z28: =($Z$20-U28)/30 -> 31.433333 | AA28: =Y28/X28*Z28 -> 677893.56 | AB28: =Y28-AA28 -> 357277.94 | AD28: =K28-AB28 -> 47895.929
A29: 52815 | B29: OCL | C29: Vehicle Lease | D29: 1.3148 | E29: 44470 | F29: 45899 | G29: 28583.98 | H29: 123356.37 | I29: 123356.37 | J29: 1180349.3 | K29: 0 | L29: 0 | M29: 0 | N29: 40742.59 | O29: 334606.56 | P29: 0 | Q29: 0 | R29: 400237.36 | T29: 0.07 | U29: =E29 -> 44470 | V29: =F29 -> 45899 | W29: =G29 -> 28583.98 | X29: =ROUNDDOWN((V29-U29)/30,0) -> 47 | Y29: =-PV((T29/12),X29,W29) -> 1172051.9 | Z29: 47 | AA29: =Y29/X29*Z29 -> 1172051.9 | AB29: =Y29-AA29 -> 0 | AD29: =K29-AB29 -> 0
A30: 59308 | B30: MMF | C30: IT Equipment Lease | D30: 5.1215 | E30: 44926 | F30: 46691 | G30: 606609.11 | H30: 16941688 | I30: 6558072.7 | J30: 21514122 | K30: 10383615 | T30: 0.07 | U30: =E30 -> 44926 | V30: =F30 -> 46691 | W30: =G30 -> 606609.11 | X30: =ROUNDDOWN((V30-U30)/30,0) -> 58 | Y30: =-PV((T30/12),X30,W30) -> 29776663 | Z30: =($Z$20-U30)/30 -> 39.533333 | AA30: =Y30/X30*Z30 -> 20296047 | AB30: =Y30-AA30 -> 9480615.7 | AD30: =K30-AB30 -> 902999.4
Z32: =AVERAGE(Z22:Z30) -> 36.544444

Sheet MMF-59308
A1: ='ITC- 59268'!A1 -> #REF!
A2: ='ITC- 59268'!A2 -> #REF!
A3: ='ITC- 59268'!A3 -> #REF!
A6: =[3]Scope!A6 -> Purpose
A7: To verify the lease working of the sample selected
A10: Summary
B11: << Link >> | C11: << As per agreement >> | D11: << As per agreement >> | E11: << Link >> | F11: << Link >> | G11: << Link >> | H11: << Link >> | I11: << Link >> | J11: << Link >>
A12: Particulars | B12: Discount Rate | C12: Commencement Date | D12: Expiration Date | E12: Addition during FY 2025-26 | F12: Amortisation during FY 2025-26 | G12: Closing Balance | H12: Interest | I12: Repayment | J12: Closing Balance | K12: ST | L12: LT
A13: As per Lease Report | B13: 0.051215 | C13: 44926 | D13: 46691 | E13: 0 | F13: 6558072.7 | G13: 10383615 | H13: 720542.53 | I13: 7279309.3 | J13: 11095181 | K13: 6902672.2 | L13: 4192508.5
A14: As per DHS Working | B14: 0.051215 | C14: 44926 | D14: 46691 | E14: 0 | F14: =SUM(C52:C63) -> 6436214.8 | G14: =D63 -> 9654322.2 | H14: =SUM(F52:F63) -> 720542.53 | I14: =-SUM(G52:G63) -> 7279309.3 | J14: =H63 -> 10488572 | K14: =H63-H76 -> 7493977 | L14: =J14-K14 -> 2994594.6
A15: Difference | B15: =B13-B14 -> 0 | C15: =C13-C14 -> 0 | D15: =D13-D14 -> 0 | E15: =E13-E14 -> 0 | F15: =F13-F14 -> 121857.92 | G15: =G13-G14 -> 729292.88 | H15: =H13-H14 -> 8.6452463e-05 | I15: =I13-I14 -> 0 | ... L15: =L13-L14 -> 1197913.9
A18: Monthly Rent | B18: 606609.11 | C18: << As per agreement >>
A19: Monthly discount rate | B19: =B14/12 -> 0.0042679167 | C19: << Link >>
A20: No of Months | B20: =ROUND(((D14-C14)/30.5),0) -> 58 | C20: << Formula >>
A21: PV of rent payments | B21: =-PV(B19,B20,B18) -> 31108372 | C21: << Formula >>
A23: Month | B23: Opening WDV | C23: Dep | D23: Closing WDV | E23: Opening Liability | F23: Interest | G23: Repayment | H23: Closing Lease Liability
A24: 44896 | B24: =$B$21 -> 31108372 | C24: =$B$21/$B$20 -> 536351.23 | D24: =B24-C24 -> 30572020 | E24: =$B$21 -> 31108372 | F24: =E24*$B$19 -> 132767.94 | G24: =-$B$18 -> -606609.11 | H24: =SUM(E24:G24) -> 30634530
A25: 44927 | B25: =D24 -> 30572020 | C25: =$B$21/$B$20 -> 536351.23 | D25: =B25-C25 -> 30035669 | E25: =H24 -> 30634530 | F25: =E25*$B$19 -> 130745.62 | G25: =-$B$18 -> -606609.11 | H25: =SUM(E25:G25) -> 30158667
A26: 44958 | B26: =D25 -> 30035669 | C26: =$B$21/$B$20 -> 536351.23 | D26: =B26-C26 -> 29499318 | E26: =H25 -> 30158667 | F26: =E26*$B$19 -> 128714.68 | G26: =-$B$18 -> -606609.11 | H26: =SUM(E26:G26) -> 29680772
A27: 44986 | B27: =D26 -> 29499318 | C27: =$B$21/$B$20 -> 536351.23 | D27: =B27-C27 -> 28962967 | E27: =H26 -> 29680772 | F27: =E27*$B$19 -> 126675.06 | G27: =-$B$18 -> -606609.11 | H27: =SUM(E27:G27) -> 29200838
A28: 45017 | B28: =D27 -> 28962967 | C28: =$B$21/$B$20 -> 536351.23 | D28: =B28-C28 -> 28426615 | E28: =H27 -> 29200838 | F28: =E28*$B$19 -> 124626.74 | G28: =-$B$18 -> -606609.11 | H28: =SUM(E28:G28) -> 28718856
A29: 45047 | B29: =D28 -> 28426615 | C29: =$B$21/$B$20 -> 536351.23 | D29: =B29-C29 -> 27890264 | E29: =H28 -> 28718856 | F29: =E29*$B$19 -> 122569.68 | G29: =-$B$18 -> -606609.11 | H29: =SUM(E29:G29) -> 28234817
A30: 45078 | B30: =D29 -> 27890264 | C30: =$B$21/$B$20 -> 536351.23 | D30: =B30-C30 -> 27353913 | E30: =H29 -> 28234817 | F30: =E30*$B$19 -> 120503.84 | G30: =-$B$18 -> -606609.11 | H30: =SUM(E30:G30) -> 27748711
A31: 45108 | B31: =D30 -> 27353913 | C31: =$B$21/$B$20 -> 536351.23 | D31: =B31-C31 -> 26817562 | E31: =H30 -> 27748711 | F31: =E31*$B$19 -> 118429.19 | G31: =-$B$18 -> -606609.11 | H31: =SUM(E31:G31) -> 27260531
A32: 45139 | B32: =D31 -> 26817562 | C32: =$B$21/$B$20 -> 536351.23 | D32: =B32-C32 -> 26281210 | E32: =H31 -> 27260531 | F32: =E32*$B$19 -> 116345.68 | G32: =-$B$18 -> -606609.11 | H32: =SUM(E32:G32) -> 26770268
A33: 45170 | B33: =D32 -> 26281210 | C33: =$B$21/$B$20 -> 536351.23 | D33: =B33-C33 -> 25744859 | E33: =H32 -> 26770268 | F33: =E33*$B$19 -> 114253.27 | G33: =-$B$18 -> -606609.11 | H33: =SUM(E33:G33) -> 26277912
A34: 45200 | B34: =D33 -> 25744859 | C34: =$B$21/$B$20 -> 536351.23 | D34: =B34-C34 -> 25208508 | E34: =H33 -> 26277912 | F34: =E34*$B$19 -> 112151.94 | G34: =-$B$18 -> -606609.11 | H34: =SUM(E34:G34) -> 25783455
A35: 45231 | B35: =D34 -> 25208508 | C35: =$B$21/$B$20 -> 536351.23 | D35: =B35-C35 -> 24672157 | E35: =H34 -> 25783455 | F35: =E35*$B$19 -> 110041.64 | G35: =-$B$18 -> -606609.11 | H35: =SUM(E35:G35) -> 25286888
A36: 45261 | B36: =D35 -> 24672157 | C36: =$B$21/$B$20 -> 536351.23 | D36: =B36-C36 -> 24135806 | E36: =H35 -> 25286888 | F36: =E36*$B$19 -> 107922.33 | G36: =-$B$18 -> -606609.11 | H36: =SUM(E36:G36) -> 24788201
... A81: 46631 | B81: =D80 -> 536351.23 | C81: =$B$21/$B$20 -> 536351.23 | D81: =B81-C81 -> -1.8393621e-08 | E81: =H80 -> 604031.16 | F81: =E81*$B$19 -> 2577.9546 | G81: =-$B$18 -> -606609.11 | H81: =SUM(E81:G81) -> -1.0760268e-06

Sheet MMF-66353
A6: Purpose
A7: To verify the lease working of the sample selected
A10: Summary
A12: Particulars | B12: Discount Rate | C12: Commencement Date | D12: Expiration Date | E12: Addition during FY 2025-26 | F12: Amortisation during FY 2025-26 | G12: Closing WDV | H12: Interest | I12: Repayment | J12: Closing Balance | K12: ST | L12: LT
A13: As per Lease Report | B13: 0.076675 | C13: 45992 | D13: 48182 | E13: 1.4217495e+08 | F13: 7898608.4 | G13: 134276343 | H13: 3542368.2 | I13: 7860320 | J13: 1.37857e+08 | K13: 13633962 | L13: 1.2422304e+08
A14: As per DHS Working | B14: 0.076675 | C14: 45992 | D14: 48182 | E14: =B20 -> 1.4217498e+08 | F14: =SUM(C25:C28) -> 7898609.9 | G14: =D28 -> 1.3427637e+08 | H14: =SUM(G25:G28) -> 3542366.1 | I14: =-SUM(F25:F28) -> 7860320 | J14: =H28 -> 1.3785702e+08 | K14: =H29-H41 -> 13721084 | L14: =H41 -> 1.2303915e+08
A15: Difference | B15: =B13-B14 -> 0 | C15: =C13-C14 -> 0 | D15: =D13-D14 -> 0 | E15: =E13-E14 -> -25.959899 | F15: =F13-F14 -> -1.4533277 | G15: =G13-G14 -> -24.506571 | H15: =H13-H14 -> 2.1198117 | I15: =I13-I14 -> 0 | ... L15: =L13-L14 -> 1183884.8
A17: Net EMI - Months 1-36 (GST benefit available) | B17: 1965080 | C17: << As per agreement - net of GST credit >>
A18: Monthly discount rate | B18: =B14/12 -> 0.0063895833 | C18: << Link >>
A19: No of Months | B19: =6*12 -> 72 | C19: << As per Agreement >>
A20: PV of rent payments | B20: =-PV(B18,36,B17,,1)-PV(B18,36,B21,,1)/(1+B18)^36 -> 1.4217498e+08 | C20: << Formula >>
A21: Gross EMI - Months 37-72 (GST benefit not available) | B21: 3069120 | C21: << As per agreement - gross, no GST credit >>
B23: Right of Use Asset | E23: Lease Liability
A24: From | B24: Opening WDV | C24: Depreciation | D24: Closing WDV | E24: Opening Liability | F24: Repayment | G24: Interest | H24: Closing Lease Liability
A25: 45992 | B25: =B20 -> 1.4217498e+08 | C25: =$B$20/$B$19 -> 1974652.5 | D25: =B25-C25 -> 1.4020032e+08 | E25: =B25 -> 1.4217498e+08 | F25: =-$B$17 -> -1965080 | G25: =(E25+F25)*$B$18 -> 895882.82 | H25: =E25+F25+G25 -> 1.4110578e+08
A26: 46023 | B26: =D25 -> 1.4020032e+08 | C26: =$B$20/$B$19 -> 1974652.5 | D26: =B26-C26 -> 1.3822567e+08 | E26: =H25 -> 1.4110578e+08 | F26: =-$B$17 -> -1965080 | G26: =(E26+F26)*$B$18 -> 889051.1 | H26: =E26+F26+G26 -> 1.4002975e+08
A27: 46054 | B27: =D26 -> 1.3822567e+08 | C27: =$B$20/$B$19 -> 1974652.5 | D27: =B27-C27 -> 1.3625102e+08 | E27: =H26 -> 1.4002975e+08 | F27: =-$B$17 -> -1965080 | G27: =(E27+F27)*$B$18 -> 882175.72 | H27: =E27+F27+G27 -> 1.3894685e+08
A28: 46082 | B28: =D27 -> 1.3625102e+08 | C28: =$B$20/$B$19 -> 1974652.5 | D28: =B28-C28 -> 1.3427637e+08 | E28: =H27 -> 1.3894685e+08 | F28: =-$B$17 -> -1965080 | G28: =(E28+F28)*$B$18 -> 875256.42 | H28: =E28+F28+G28 -> 1.3785702e+08
A29: 46113 | B29: =D28 -> 1.3427637e+08 | C29: =$B$20/$B$19 -> 1974652.5 | D29: =B29-C29 -> 1.3230172e+08 | E29: =H28 -> 1.3785702e+08 | F29: =-$B$17 -> -1965080 | G29: =(E29+F29)*$B$18 -> 868292.9 | H29: =E29+F29+G29 -> 1.3676024e+08
A30: 46143 | B30: =D29 -> 1.3230172e+08 | C30: =$B$20/$B$19 -> 1974652.5 | D30: =B30-C30 -> 1.3032706e+08 | E30: =H29 -> 1.3676024e+08 | F30: =-$B$17 -> -1965080 | G30: =(E30+F30)*$B$18 -> 861284.88 | H30: =E30+F30+G30 -> 1.3565644e+08
A31: 46174 | B31: =D30 -> 1.3032706e+08 | C31: =$B$20/$B$19 -> 1974652.5 | D31: =B31-C31 -> 1.2835241e+08 | E31: =H30 -> 1.3565644e+08 | F31: =-$B$17 -> -1965080 | G31: =(E31+F31)*$B$18 -> 854232.09 | H31: =E31+F31+G31 -> 1.3454559e+08
A32: 46204 | B32: =D31 -> 1.2835241e+08 | C32: =$B$20/$B$19 -> 1974652.5 | D32: =B32-C32 -> 1.2637776e+08 | E32: =H31 -> 1.3454559e+08 | F32: =-$B$17 -> -1965080 | G32: =(E32+F32)*$B$18 -> 847134.24 | H32: =E32+F32+G32 -> 1.3342765e+08
A33: 46235 | B33: =D32 -> 1.2637776e+08 | C33: =$B$20/$B$19 -> 1974652.5 | D33: =B33-C33 -> 1.2440311e+08 | E33: =H32 -> 1.3342765e+08 | F33: =-$B$17 -> -1965080 | G33: =(E33+F33)*$B$18 -> 839991.03 | H33: =E33+F33+G33 -> 1.3230256e+08
A34: 46266 | B34: =D33 -> 1.2440311e+08 | C34: =$B$20/$B$19 -> 1974652.5 | D34: =B34-C34 -> 1.2242845e+08 | E34: =H33 -> 1.3230256e+08 | F34: =-$B$17 -> -1965080 | G34: =(E34+F34)*$B$18 -> 832802.18 | H34: =E34+F34+G34 -> 1.3117028e+08
A35: 46296 | B35: =D34 -> 1.2242845e+08 | C35: =$B$20/$B$19 -> 1974652.5 | D35: =B35-C35 -> 1.204538e+08 | E35: =H34 -> 1.3117028e+08 | F35: =-$B$17 -> -1965080 | G35: =(E35+F35)*$B$18 -> 825567.4 | H35: =E35+F35+G35 -> 1.3003077e+08
A36: 46327 | B36: =D35 -> 1.204538e+08 | C36: =$B$20/$B$19 -> 1974652.5 | D36: =B36-C36 -> 1.1847915e+08 | E36: =H35 -> 1.3003077e+08 | F36: =-$B$17 -> -1965080 | G36: =(E36+F36)*$B$18 -> 818286.39 | H36: =E36+F36+G36 -> 1.2888397e+08
A37: 46357 | B37: =D36 -> 1.1847915e+08 | C37: =$B$20/$B$19 -> 1974652.5 | D37: =B37-C37 -> 1.165045e+08 | E37: =H36 -> 1.2888397e+08 | F37: =-$B$17 -> -1965080 | G37: =(E37+F37)*$B$18 -> 810958.85 | H37: =E37+F37+G37 -> 1.2772985e+08
... A60: 47058 | B60: =D59 -> 73062141 | C60: =$B$20/$B$19 -> 1974652.5 | D60: =B60-C60 -> 71087489 | E60: =H59 -> 1.003873e+08 | F60: =-$B$17 -> -1965080 | G60: =(E60+F60)*$B$18 -> 628876.96 | H60: =E60+F60+G60 -> 99051094
A61: 47088 | B61: =D60 -> 71087489 | C61: =$B$20/$B$19 -> 1974652.5 | D61: =B61-C61 -> 69112836 | E61: =H60 -> 99051094 | F61: =-$B$21 -> -3069120 | G61: =(E61+F61)*$B$18 -> 613284.82 | H61: =E61+F61+G61 -> 96595259
A62: 47119 | B62: =D61 -> 69112836 | C62: =$B$20/$B$19 -> 1974652.5 | D62: =B62-C62 -> 67138184 | E62: =H61 -> 96595259 | F62: =-$B$21 -> -3069120 | G62: =(E62+F62)*$B$18 -> 597593.06 | H62: =E62+F62+G62 -> 94123732
A63: 47150 | B63: =D62 -> 67138184 | C63: =$B$20/$B$19 -> 1974652.5 | D63: =B63-C63 -> 65163531 | E63: =H62 -> 94123732 | F63: =-$B$21 -> -3069120 | G63: =(E63+F63)*$B$18 -> 581801.03 | H63: =E63+F63+G63 -> 91636413
A64: 47178 | B64: =D63 -> 65163531 | C64: =$B$20/$B$19 -> 1974652.5 | D64: =B64-C64 -> 63188879 | E64: =H63 -> 91636413 | F64: =-$B$21 -> -3069120 | G64: =(E64+F64)*$B$18 -> 565908.1 | H64: =E64+F64+G64 -> 89133201
A65: 47209 | B65: =D64 -> 63188879 | C65: =$B$20/$B$19 -> 1974652.5 | D65: =B65-C65 -> 61214226 | E65: =H64 -> 89133201 | F65: =-$B$21 -> -3069120 | G65: =(E65+F65)*$B$18 -> 549913.62 | H65: =E65+F65+G65 -> 86613995
A66: 47239 | B66: =D65 -> 61214226 | C66: =$B$20/$B$19 -> 1974652.5 | D66: =B66-C66 -> 59239574 | E66: =H65 -> 86613995 | F66: =-$B$21 -> -3069120 | G66: =(E66+F66)*$B$18 -> 533816.94 | H66: =E66+F66+G66 -> 84078691
A67: 47270 | B67: =D66 -> 59239574 | C67: =$B$20/$B$19 -> 1974652.5 | D67: =B67-C67 -> 57264921 | E67: =H66 -> 84078691 | F67: =-$B$21 -> -3069120 | G67: =(E67+F67)*$B$18 -> 517617.41 | H67: =E67+F67+G67 -> 81527189
A68: 47300 | B68: =D67 -> 57264921 | C68: =$B$20/$B$19 -> 1974652.5 | D68: =B68-C68 -> 55290269 | E68: =H67 -> 81527189 | F68: =-$B$21 -> -3069120 | G68: =(E68+F68)*$B$18 -> 501314.37 | H68: =E68+F68+G68 -> 78959383
A69: 47331 | B69: =D68 -> 55290269 | C69: =$B$20/$B$19 -> 1974652.5 | D69: =B69-C69 -> 53315617 | E69: =H68 -> 78959383 | F69: =-$B$21 -> -3069120 | G69: =(E69+F69)*$B$18 -> 484907.16 | H69: =E69+F69+G69 -> 76375170
A70: 47362 | B70: =D69 -> 53315617 | C70: =$B$20/$B$19 -> 1974652.5 | D70: =B70-C70 -> 51340964 | E70: =H69 -> 76375170 | F70: =-$B$21 -> -3069120 | G70: =(E70+F70)*$B$18 -> 468395.12 | H70: =E70+F70+G70 -> 73774446
A71: 47392 | B71: =D70 -> 51340964 | C71: =$B$20/$B$19 -> 1974652.5 | D71: =B71-C71 -> 49366312 | E71: =H70 -> 73774446 | F71: =-$B$21 -> -3069120 | G71: =(E71+F71)*$B$18 -> 451777.57 | H71: =E71+F71+G71 -> 71157103
A72: 47423 | B72: =D71 -> 49366312 | C72: =$B$20/$B$19 -> 1974652.5 | D72: =B72-C72 -> 47391659 | E72: =H71 -> 71157103 | F72: =-$B$21 -> -3069120 | G72: =(E72+F72)*$B$18 -> 435053.84 | H72: =E72+F72+G72 -> 68523037
...

Sheet MMF-66354
A3: Purpose
A4: To verify the lease working of the sample selected
A7: Summary
A9: Particulars | B9: Discount Rate | C9: Commencement Date | D9: Expiration Date | E9: Addition during FY 2025-26 | F9: Amortisation during FY 2025-26 | G9: Closing WDV | H9: Interest | I9: Repayment | J9: Closing Balance | K9: ST | L9: LT
